Workbook

Sheet Read me
A1: SiteGuard — neatHack 2026 financial model
A2: Hypothetical planning simulation; not company performance. USD. October 2026–September 2027.
A3: Proposed prices are user hypotheses. All demand, churn, site use, non-token costs, staffing and cash are author estimates.
A4: Blue cells are editable inputs. Black cells are formulas. All forecasts open with zero customers and no financing.
A5: Revenue uses average active customers and prorated monthly charges. Exit MRR uses ending paid customers.
A6: Model references: OpenAI GPT-5 mini $0.25 input/$2 output per million; GPT-5 $1.25/$10. Standard uncached reference rates, reviewed 12 Oct 2026.
A7: Stripe US domestic-card reference 2.9% + $0.30; geographic applicability is unconfirmed. Billing software 0.7% is unverified allowance.
A8: See SiteGuard_Financial_Report.pdf for supplier URLs, detailed assumptions, risks, scope and recommendations.
A9: MVP features are intended, not independently verified shipped. Production connectors, rollback, multi-region, teams and advanced analytics are future.
A10: Scenarios: Base, Conservative, Optimistic, Guardrailed and six independent stresses. Scenario sheets inherit visible Inputs/Pricing except stated blue overrides.
A11: Acquisition spend = new paid customers x CAC. Lower conversion lowers spending as well as revenue; fixed traffic-budget losses may be worse.
A12: Negative cash is a financing gap, not an ability to operate unfunded. Founder cash pay = zero is a subsidy, not market compensation.
... A15: This portable workbook reproduces the checked native model with standard Excel formulas; it is not a live connection to the app.

Sheet Scenario summary
A1: Hypothetical case | B1: Exit paid | C1: Exit MRR | D1: Year revenue | E1: Service cost | F1: Operating expenses | G1: Operating profit/(loss) | H1: Year GM | I1: Max cash need | J1: Exit cash from $15k
A2: Base | B2: =Base!M73 -> 216.49017 | C2: =Base!M76 -> 5195.764 | D2: =SUM(Base!B77:M77) -> 26670.625 | E2: =SUM(Base!B83:M83) -> 23889.684 | F2: =SUM(Base!B91:M91) -> 37564.456 | G2: =SUM(Base!B92:M92) -> -34783.516 | H2: =IFERROR((D2-E2)/D2,0) -> 0.10426979 | I2: =MAX(0,-MIN(Base!B93:M93)) -> 34783.516 | J2: =Base!M96 -> -19783.516
A3: Conservative | B3: =Conservative!M73 -> 36.726934 | C3: =Conservative!M76 -> 591.30364 | D3: =SUM(Conservative!B77:M77) -> 3563.4621 | E3: =SUM(Conservative!B83:M83) -> 5641.8527 | F3: =SUM(Conservative!B91:M91) -> 30356.088 | G3: =SUM(Conservative!B92:M92) -> -32434.479 | H3: =IFERROR((D3-E3)/D3,0) -> -0.58325038 | I3: =MAX(0,-MIN(Conservative!B93:M93)) -> 32434.479 | J3: =Conservative!M96 -> -17434.479
A4: Optimistic | B4: =Optimistic!M73 -> 948.80608 | C4: =Optimistic!M76 -> 28938.585 | D4: =SUM(Optimistic!B77:M77) -> 130679.11 | E4: =SUM(Optimistic!B83:M83) -> 98525.66 | F4: =SUM(Optimistic!B91:M91) -> 58621.801 | G4: =SUM(Optimistic!B92:M92) -> -26468.351 | H4: =IFERROR((D4-E4)/D4,0) -> 0.24604889 | I4: =MAX(0,-MIN(Optimistic!B93:M93)) -> 26468.351 | J4: =Optimistic!M96 -> -11468.351
A5: Guardrailed | B5: =Guardrailed!M73 -> 216.49017 | C5: =Guardrailed!M76 -> 5195.764 | D5: =SUM(Guardrailed!B77:M77) -> 26670.625 | E5: =SUM(Guardrailed!B83:M83) -> 9681.2589 | F5: =SUM(Guardrailed!B91:M91) -> 25564.456 | G5: =SUM(Guardrailed!B92:M92) -> -8575.0904 | H5: =IFERROR((D5-E5)/D5,0) -> 0.63700667 | I5: =MAX(0,-MIN(Guardrailed!B93:M93)) -> 8762.9553 | J5: =Guardrailed!M96 -> 6424.9096
A6: AI 2x | B6: ='AI 2x'!M73 -> 216.49017 | C6: ='AI 2x'!M76 -> 5195.764 | D6: =SUM('AI 2x'!B77:M77) -> 26670.625 | E6: =SUM('AI 2x'!B83:M83) -> 23901.916 | F6: =SUM('AI 2x'!B91:M91) -> 37564.456 | G6: =SUM('AI 2x'!B92:M92) -> -34795.748 | H6: =IFERROR((D6-E6)/D6,0) -> 0.10381115 | I6: =MAX(0,-MIN('AI 2x'!B93:M93)) -> 34795.748 | J6: ='AI 2x'!M96 -> -19795.748
A7: CAC +50pct | B7: ='CAC +50pct'!M73 -> 216.49017 | C7: ='CAC +50pct'!M76 -> 5195.764 | D7: =SUM('CAC +50pct'!B77:M77) -> 26670.625 | E7: =SUM('CAC +50pct'!B83:M83) -> 23889.684 | F7: =SUM('CAC +50pct'!B91:M91) -> 42696.684 | G7: =SUM('CAC +50pct'!B92:M92) -> -39915.744 | H7: =IFERROR((D7-E7)/D7,0) -> 0.10426979 | I7: =MAX(0,-MIN('CAC +50pct'!B93:M93)) -> 39915.744 | J7: ='CAC +50pct'!M96 -> -24915.744
A8: Conversion -25pct | B8: ='Conversion -25pct'!M73 -> 162.36763 | C8: ='Conversion -25pct'!M76 -> 3896.823 | D8: =SUM('Conversion -25pct'!B77:M77) -> 20002.969 | E8: =SUM('Conversion -25pct'!B83:M83) -> 19777.819 | F8: =SUM('Conversion -25pct'!B91:M91) -> 34998.342 | G8: =SUM('Conversion -25pct'!B92:M92) -> -34773.193 | H8: =IFERROR((D8-E8)/D8,0) -> 0.011255804 | I8: =MAX(0,-MIN('Conversion -25pct'!B93:M93)) -> 34773.193 | J8: ='Conversion -25pct'!M96 -> -19773.193
A9: Monitoring 5x | B9: ='Monitoring 5x'!M73 -> 216.49017 | C9: ='Monitoring 5x'!M76 -> 5195.764 | D9: =SUM('Monitoring 5x'!B77:M77) -> 26670.625 | E9: =SUM('Monitoring 5x'!B83:M83) -> 94369.894 | F9: =SUM('Monitoring 5x'!B91:M91) -> 37564.456 | G9: =SUM('Monitoring 5x'!B92:M92) -> -105263.73 | H9: =IFERROR((D9-E9)/D9,0) -> -2.5383458 | I9: =MAX(0,-MIN('Monitoring 5x'!B93:M93)) -> 105263.73 | J9: ='Monitoring 5x'!M96 -> -90263.726
A10: Incidents 3x | B10: ='Incidents 3x'!M73 -> 216.49017 | C10: ='Incidents 3x'!M76 -> 5195.764 | D10: =SUM('Incidents 3x'!B77:M77) -> 26670.625 | E10: =SUM('Incidents 3x'!B83:M83) -> 23993.104 | F10: =SUM('Incidents 3x'!B91:M91) -> 37564.456 | G10: =SUM('Incidents 3x'!B92:M92) -> -34886.935 | H10: =IFERROR((D10-E10)/D10,0) -> 0.10039213 | I10: =MAX(0,-MIN('Incidents 3x'!B93:M93)) -> 34886.935 | J10: ='Incidents 3x'!M96 -> -19886.935
A11: Churn +2pp | B11: ='Churn +2pp'!M73 -> 199.6881 | C11: ='Churn +2pp'!M76 -> 4792.5145 | D11: =SUM('Churn +2pp'!B77:M77) -> 25165.577 | E11: =SUM('Churn +2pp'!B83:M83) -> 23049.72 | F11: =SUM('Churn +2pp'!B91:M91) -> 37564.456 | G11: =SUM('Churn +2pp'!B92:M92) -> -35448.599 | H11: =IFERROR((D11-E11)/D11,0) -> 0.084077428 | I11: =MAX(0,-MIN('Churn +2pp'!B93:M93)) -> 35448.599 | J11: ='Churn +2pp'!M96 -> -20448.599

Sheet Inputs
A1: Editable assumption | B1: Base input | C1: Basis
A2: Initial monthly signups | B2: 150 | C2: Hypothetical planning assumption
A3: Monthly signup growth | B3: 0.1 | C3: Hypothetical planning assumption
A4: Paid conversion rate | B4: 0.08 | C4: Hypothetical planning assumption
A5: Monthly paid churn | B5: 0.04 | C5: Hypothetical planning assumption
A6: Monthly free churn | B6: 0.15 | C6: Hypothetical planning assumption
A7: Blended acquisition CAC | B7: 40 | C7: Hypothetical planning assumption
A8: Incidents per website month | B8: 0.4 | C8: Hypothetical planning assumption
A9: AI analysis share | B9: 0.6 | C9: Hypothetical planning assumption
A10: AI input tokens per attempt | B10: 6000 | C10: Hypothetical planning assumption
A11: AI billed output tokens per attempt | B11: 1000 | C11: Hypothetical planning assumption
A12: AI attempt multiplier | B12: 1.2 | C12: Hypothetical planning assumption
A13: Tool execution cost per attempt | B13: 0.01 | C13: Hypothetical planning assumption
... A52: Incident volume multiplier | B52: 1 | C52: Hypothetical planning assumption
A53: Forecast start date | B53: 2026-10-01 | C53: Hypothetical planning assumption
A54: Starting cash 5k | B54: 5000 | C54: Hypothetical alternative starting cash
A55: Starting cash 15k | B55: 15000 | C55: Hypothetical alternative starting cash
A56: Starting cash 30k | B56: 30000 | C56: Hypothetical alternative starting cash

Sheet Pricing
A1: Plan | B1: Monthly price | C1: Paid acquisition mix | D1: Sites/account | E1: Interval minutes | F1: AI eligibility
A2: Free | B2: 0 | C2: 0 | D2: 1 | E2: 15 | F2: 0
A3: Starter | B3: 9 | C3: 0.6 | D3: 3 | E3: 5 | F3: 1
A4: Pro | B4: 29 | C4: 0.3 | D4: 10 | E4: 5 | F4: 1
A5: Business | B5: 99 | C5: 0.1 | D5: 30 | E5: 5 | F5: 1

Sheet Base
A1: Base — hypothetical 12-month forecast
A4: Initial monthly signups | B4: =Inputs!$B$2 -> 150
A5: Monthly signup growth | B5: =Inputs!$B$3 -> 0.1
A6: Paid conversion rate | B6: =Inputs!$B$4 -> 0.08
A7: Monthly paid churn | B7: =Inputs!$B$5 -> 0.04
A8: Monthly free churn | B8: =Inputs!$B$6 -> 0.15
A9: Blended acquisition CAC | B9: =Inputs!$B$7 -> 40
A10: Staff monthly budget | B10: =Inputs!$B$45 -> 3000
A11: AI cost stress multiplier | B11: =Inputs!$B$50 -> 1
A12: Monitoring frequency multiplier | B12: =Inputs!$B$51 -> 1
A13: Incident volume multiplier | B13: =Inputs!$B$52 -> 1
A17: Free | B17: =Pricing!B2 -> 0 | C17: =Pricing!C2 -> 0 | D17: =Pricing!D2 -> 1 | E17: =Pricing!E2 -> 15 | F17: =Pricing!F2 -> 0
A18: Starter | B18: =Pricing!B3 -> 9 | C18: =Pricing!C3 -> 0.6 | D18: =Pricing!D3 -> 3 | E18: =Pricing!E3 -> 5 | F18: =Pricing!F3 -> 1
A19: Pro | B19: =Pricing!B4 -> 29 | C19: =Pricing!C4 -> 0.3 | D19: =Pricing!D4 -> 10 | E19: =Pricing!E4 -> 5 | F19: =Pricing!F4 -> 1
A20: Business | B20: =Pricing!B5 -> 99 | C20: =Pricing!C5 -> 0.1 | D20: =Pricing!D5 -> 30 | E20: =Pricing!E5 -> 5 | F20: =Pricing!F5 -> 1
B25: 46296 | C25: 46327 | D25: 46357 | E25: 46388 | F25: 46419 | G25: 46447 | H25: 46478 | I25: 46508 | J25: 46539 | K25: 46569 | L25: 46600 | M25: 46631
A26: New signups | B26: =$B$4 -> 150 | C26: =B26*(1+$B$5) -> 165 | D26: =C26*(1+$B$5) -> 181.5 | E26: =D26*(1+$B$5) -> 199.65 | F26: =E26*(1+$B$5) -> 219.615 | G26: =F26*(1+$B$5) -> 241.5765 | H26: =G26*(1+$B$5) -> 265.73415 | I26: =H26*(1+$B$5) -> 292.30757 | J26: =I26*(1+$B$5) -> 321.53832 | ... M26: =L26*(1+$B$5) -> 427.96751
A27: New paid | B27: =B26*$B$6 -> 12 | C27: =C26*$B$6 -> 13.2 | D27: =D26*$B$6 -> 14.52 | E27: =E26*$B$6 -> 15.972 | F27: =F26*$B$6 -> 17.5692 | G27: =G26*$B$6 -> 19.32612 | H27: =H26*$B$6 -> 21.258732 | I27: =I26*$B$6 -> 23.384605 | ... M27: =M26*$B$6 -> 34.2374
A28: New free | B28: =B26-B27 -> 138 | C28: =C26-C27 -> 151.8 | D28: =D26-D27 -> 166.98 | E28: =E26-E27 -> 183.678 | F28: =F26-F27 -> 202.0458 | G28: =G26-G27 -> 222.25038 | H28: =H26-H27 -> 244.47542 | I28: =I26-I27 -> 268.92296 | ... M28: =M26-M27 -> 393.73011
A31: Free | Opening accounts | B31: =0 -> 0 | C31: =B34 -> 138 | D31: =C34 -> 269.1 | E31: =D34 -> 395.715 | F31: =E34 -> 520.03575 | G31: =F34 -> 644.07619 | H31: =G34 -> 769.71514 | I31: =H34 -> 898.73329 | J31: =I34 -> 1032.8463 | ... M31: =L34 -> 1482.547
A32: Free | New accounts | B32: =B28 -> 138 | C32: =C28 -> 151.8 | D32: =D28 -> 166.98 | E32: =E28 -> 183.678 | F32: =F28 -> 202.0458 | G32: =G28 -> 222.25038 | H32: =H28 -> 244.47542 | I32: =I28 -> 268.92296 | ... M32: =M28 -> 393.73011
A33: Free | Churned accounts | B33: =B31*$B$8 -> 0 | C33: =C31*$B$8 -> 20.7 | D33: =D31*$B$8 -> 40.365 | E33: =E31*$B$8 -> 59.35725 | F33: =F31*$B$8 -> 78.005363 | G33: =G31*$B$8 -> 96.611428 | H33: =H31*$B$8 -> 115.45727 | I33: =I31*$B$8 -> 134.80999 | ... M33: =M31*$B$8 -> 222.38204
A34: Free | Ending accounts | B34: =B31+B32-B33 -> 138 | C34: =C31+C32-C33 -> 269.1 | D34: =D31+D32-D33 -> 395.715 | E34: =E31+E32-E33 -> 520.03575 | F34: =F31+F32-F33 -> 644.07619 | G34: =G31+G32-G33 -> 769.71514 | H34: =H31+H32-H33 -> 898.73329 | I34: =I31+I32-I33 -> 1032.8463 | ... M34: =M31+M32-M33 -> 1653.895
A35: Free | Average accounts | B35: =(B31+B34)/2 -> 69 | C35: =(C31+C34)/2 -> 203.55 | D35: =(D31+D34)/2 -> 332.4075 | E35: =(E31+E34)/2 -> 457.87538 | F35: =(F31+F34)/2 -> 582.05597 | G35: =(G31+G34)/2 -> 706.89566 | H35: =(H31+H34)/2 -> 834.22421 | I35: =(I31+I34)/2 -> 965.78977 | ... M35: =(M31+M34)/2 -> 1568.221
A36: Free | Revenue | B36: =B35*$B$17 -> 0 | C36: =C35*$B$17 -> 0 | D36: =D35*$B$17 -> 0 | E36: =E35*$B$17 -> 0 | F36: =F35*$B$17 -> 0 | G36: =G35*$B$17 -> 0 | H36: =H35*$B$17 -> 0 | I36: =I35*$B$17 -> 0 | ... M36: =M35*$B$17 -> 0
A37: Free | Monitoring checks | B37: =(B35*$D$17)*DAY(EOMONTH(B$25,0))*1440/$E$17*$B$12 -> 205344 | C37: =(C35*$D$17)*DAY(EOMONTH(C$25,0))*1440/$E$17*$B$12 -> 586224 | D37: =(D35*$D$17)*DAY(EOMONTH(D$25,0))*1440/$E$17*$B$12 -> 989244.72 | E37: =(E35*$D$17)*DAY(EOMONTH(E$25,0))*1440/$E$17*$B$12 -> 1362637.1 | F37: =(F35*$D$17)*DAY(EOMONTH(F$25,0))*1440/$E$17*$B$12 -> 1564566.4 | G37: =(G35*$D$17)*DAY(EOMONTH(G$25,0))*1440/$E$17*$B$12 -> 2103721.5 | H37: =(H35*$D$17)*DAY(EOMONTH(H$25,0))*1440/$E$17*$B$12 -> 2402565.7 | I37: =(I35*$D$17)*DAY(EOMONTH(I$25,0))*1440/$E$17*$B$12 -> 2874190.4 | ... M37: =(M35*$D$17)*DAY(EOMONTH(M$25,0))*1440/$E$17*$B$12 -> 4516476.4
A38: Free | AI diagnoses | B38: =(B35*$D$17)*Inputs!$B$8*$B$13*Inputs!$B$9*$F$17 -> 0 | C38: =(C35*$D$17)*Inputs!$B$8*$B$13*Inputs!$B$9*$F$17 -> 0 | D38: =(D35*$D$17)*Inputs!$B$8*$B$13*Inputs!$B$9*$F$17 -> 0 | E38: =(E35*$D$17)*Inputs!$B$8*$B$13*Inputs!$B$9*$F$17 -> 0 | F38: =(F35*$D$17)*Inputs!$B$8*$B$13*Inputs!$B$9*$F$17 -> 0 | G38: =(G35*$D$17)*Inputs!$B$8*$B$13*Inputs!$B$9*$F$17 -> 0 | H38: =(H35*$D$17)*Inputs!$B$8*$B$13*Inputs!$B$9*$F$17 -> 0 | I38: =(I35*$D$17)*Inputs!$B$8*$B$13*Inputs!$B$9*$F$17 -> 0 | ... M38: =(M35*$D$17)*Inputs!$B$8*$B$13*Inputs!$B$9*$F$17 -> 0
A39: Free | Variable service expense | B39: =B37/1000*(Inputs!$B$19+Inputs!$B$20+Inputs!$B$21+Inputs!$B$22+Inputs!$B$23+Inputs!$B$24)+B38*((((Inputs!$B$10*Inputs!$B$15+Inputs!$B$11*Inputs!$B$16)*(1-Inputs!$B$14)+(Inputs!$B$10*Inputs!$B$17+Inputs!$B$11*Inputs!$B$18)*Inputs!$B$14)/1000000*Inputs!$B$12)*$B$11+Inputs!$B$12*Inputs!$B$13)+(B35*$D$17)*Inputs!$B$25*Inputs!$B$26+((B35*$D$17)*Inputs!$B$8*$B$13)*Inputs!$B$27*Inputs!$B$28+B36*(Inputs!$B$29+Inputs!$B$31) -> 35.10168 | C39: =C37/1000*(Inputs!$B$19+Inputs!$B$20+Inputs!$B$21+Inputs!$B$22+Inputs!$B$23+Inputs!$B$24)+C38*((((Inputs!$B$10*Inputs!$B$15+Inputs!$B$11*Inputs!$B$16)*(1-Inputs!$B$14)+(Inputs!$B$10*Inputs!$B$17+Inputs!$B$11*Inputs!$B$18)*Inputs!$B$14)/1000000*Inputs!$B$12)*$B$11+Inputs!$B$12*Inputs!$B$13)+(C35*$D$17)*Inputs!$B$25*Inputs!$B$26+((C35*$D$17)*Inputs!$B$8*$B$13)*Inputs!$B$27*Inputs!$B$28+C36*(Inputs!$B$29+Inputs!$B$31) -> 100.22802 | D39: =D37/1000*(Inputs!$B$19+Inputs!$B$20+Inputs!$B$21+Inputs!$B$22+Inputs!$B$23+Inputs!$B$24)+D38*((((Inputs!$B$10*Inputs!$B$15+Inputs!$B$11*Inputs!$B$16)*(1-Inputs!$B$14)+(Inputs!$B$10*Inputs!$B$17+Inputs!$B$11*Inputs!$B$18)*Inputs!$B$14)/1000000*Inputs!$B$12)*$B$11+Inputs!$B$12*Inputs!$B$13)+(D35*$D$17)*Inputs!$B$25*Inputs!$B$26+((D35*$D$17)*Inputs!$B$8*$B$13)*Inputs!$B$27*Inputs!$B$28+D36*(Inputs!$B$29+Inputs!$B$31) -> 169.10234 | E39: =E37/1000*(Inputs!$B$19+Inputs!$B$20+Inputs!$B$21+Inputs!$B$22+Inputs!$B$23+Inputs!$B$24)+E38*((((Inputs!$B$10*Inputs!$B$15+Inputs!$B$11*Inputs!$B$16)*(1-Inputs!$B$14)+(Inputs!$B$10*Inputs!$B$17+Inputs!$B$11*Inputs!$B$18)*Inputs!$B$14)/1000000*Inputs!$B$12)*$B$11+Inputs!$B$12*Inputs!$B$13)+(E35*$D$17)*Inputs!$B$25*Inputs!$B$26+((E35*$D$17)*Inputs!$B$8*$B$13)*Inputs!$B$27*Inputs!$B$28+E36*(Inputs!$B$29+Inputs!$B$31) -> 232.93036 | F39: =F37/1000*(Inputs!$B$19+Inputs!$B$20+Inputs!$B$21+Inputs!$B$22+Inputs!$B$23+Inputs!$B$24)+F38*((((Inputs!$B$10*Inputs!$B$15+Inputs!$B$11*Inputs!$B$16)*(1-Inputs!$B$14)+(Inputs!$B$10*Inputs!$B$17+Inputs!$B$11*Inputs!$B$18)*Inputs!$B$14)/1000000*Inputs!$B$12)*$B$11+Inputs!$B$12*Inputs!$B$13)+(F35*$D$17)*Inputs!$B$25*Inputs!$B$26+((F35*$D$17)*Inputs!$B$8*$B$13)*Inputs!$B$27*Inputs!$B$28+F36*(Inputs!$B$29+Inputs!$B$31) -> 267.60605 | G39: =G37/1000*(Inputs!$B$19+Inputs!$B$20+Inputs!$B$21+Inputs!$B$22+Inputs!$B$23+Inputs!$B$24)+G38*((((Inputs!$B$10*Inputs!$B$15+Inputs!$B$11*Inputs!$B$16)*(1-Inputs!$B$14)+(Inputs!$B$10*Inputs!$B$17+Inputs!$B$11*Inputs!$B$18)*Inputs!$B$14)/1000000*Inputs!$B$12)*$B$11+Inputs!$B$12*Inputs!$B$13)+(G35*$D$17)*Inputs!$B$25*Inputs!$B$26+((G35*$D$17)*Inputs!$B$8*$B$13)*Inputs!$B$27*Inputs!$B$28+G36*(Inputs!$B$29+Inputs!$B$31) -> 359.61196 | H39: =H37/1000*(Inputs!$B$19+Inputs!$B$20+Inputs!$B$21+Inputs!$B$22+Inputs!$B$23+Inputs!$B$24)+H38*((((Inputs!$B$10*Inputs!$B$15+Inputs!$B$11*Inputs!$B$16)*(1-Inputs!$B$14)+(Inputs!$B$10*Inputs!$B$17+Inputs!$B$11*Inputs!$B$18)*Inputs!$B$14)/1000000*Inputs!$B$12)*$B$11+Inputs!$B$12*Inputs!$B$13)+(H35*$D$17)*Inputs!$B$25*Inputs!$B$26+((H35*$D$17)*Inputs!$B$8*$B$13)*Inputs!$B$27*Inputs!$B$28+H36*(Inputs!$B$29+Inputs!$B$31) -> 410.772 | I39: =I37/1000*(Inputs!$B$19+Inputs!$B$20+Inputs!$B$21+Inputs!$B$22+Inputs!$B$23+Inputs!$B$24)+I38*((((Inputs!$B$10*Inputs!$B$15+Inputs!$B$11*Inputs!$B$16)*(1-Inputs!$B$14)+(Inputs!$B$10*Inputs!$B$17+Inputs!$B$11*Inputs!$B$18)*Inputs!$B$14)/1000000*Inputs!$B$12)*$B$11+Inputs!$B$12*Inputs!$B$13)+(I35*$D$17)*Inputs!$B$25*Inputs!$B$26+((I35*$D$17)*Inputs!$B$8*$B$13)*Inputs!$B$27*Inputs!$B$28+I36*(Inputs!$B$29+Inputs!$B$31) -> 491.31657 | ... M39: =M37/1000*(Inputs!$B$19+Inputs!$B$20+Inputs!$B$21+Inputs!$B$22+Inputs!$B$23+Inputs!$B$24)+M38*((((Inputs!$B$10*Inputs!$B$15+Inputs!$B$11*Inputs!$B$16)*(1-Inputs!$B$14)+(Inputs!$B$10*Inputs!$B$17+Inputs!$B$11*Inputs!$B$18)*Inputs!$B$14)/1000000*Inputs!$B$12)*$B$11+Inputs!$B$12*Inputs!$B$13)+(M35*$D$17)*Inputs!$B$25*Inputs!$B$26+((M35*$D$17)*Inputs!$B$8*$B$13)*Inputs!$B$27*Inputs!$B$28+M36*(Inputs!$B$29+Inputs!$B$31) -> 772.19201
A41: Starter | Opening accounts | B41: =0 -> 0 | C41: =B44 -> 7.2 | D41: =C44 -> 14.832 | E41: =D44 -> 22.95072 | F41: =E44 -> 31.615891 | G41: =F44 -> 40.892776 | H41: =G44 -> 50.852737 | I41: =H44 -> 61.573866 | J41: =I44 -> 73.141675 | ... M41: =L44 -> 113.90798
A42: Starter | New accounts | B42: =B27*$C$18 -> 7.2 | C42: =C27*$C$18 -> 7.92 | D42: =D27*$C$18 -> 8.712 | E42: =E27*$C$18 -> 9.5832 | F42: =F27*$C$18 -> 10.54152 | G42: =G27*$C$18 -> 11.595672 | H42: =H27*$C$18 -> 12.755239 | I42: =I27*$C$18 -> 14.030763 | ... M42: =M27*$C$18 -> 20.54244
A43: Starter | Churned accounts | B43: =B41*$B$7 -> 0 | C43: =C41*$B$7 -> 0.288 | D43: =D41*$B$7 -> 0.59328 | E43: =E41*$B$7 -> 0.9180288 | F43: =F41*$B$7 -> 1.2646356 | G43: =G41*$B$7 -> 1.635711 | H43: =H41*$B$7 -> 2.0341095 | I43: =I41*$B$7 -> 2.4629547 | ... M43: =M41*$B$7 -> 4.5563192
A44: Starter | Ending accounts | B44: =B41+B42-B43 -> 7.2 | C44: =C41+C42-C43 -> 14.832 | D44: =D41+D42-D43 -> 22.95072 | E44: =E41+E42-E43 -> 31.615891 | F44: =F41+F42-F43 -> 40.892776 | G44: =G41+G42-G43 -> 50.852737 | H44: =H41+H42-H43 -> 61.573866 | I44: =I41+I42-I43 -> 73.141675 | ... M44: =M41+M42-M43 -> 129.8941
A45: Starter | Average accounts | B45: =(B41+B44)/2 -> 3.6 | C45: =(C41+C44)/2 -> 11.016 | D45: =(D41+D44)/2 -> 18.89136 | E45: =(E41+E44)/2 -> 27.283306 | F45: =(F41+F44)/2 -> 36.254333 | G45: =(G41+G44)/2 -> 45.872756 | H45: =(H41+H44)/2 -> 56.213301 | I45: =(I41+I44)/2 -> 67.357771 | ... M45: =(M41+M44)/2 -> 121.90104
A46: Starter | Revenue | B46: =B45*$B$18 -> 32.4 | C46: =C45*$B$18 -> 99.144 | D46: =D45*$B$18 -> 170.02224 | E46: =E45*$B$18 -> 245.54975 | F46: =F45*$B$18 -> 326.289 | G46: =G45*$B$18 -> 412.8548 | H46: =H45*$B$18 -> 505.91971 | I46: =I45*$B$18 -> 606.21993 | ... M46: =M45*$B$18 -> 1097.1094
A47: Starter | Monitoring checks | B47: =(B45*$D$18)*DAY(EOMONTH(B$25,0))*1440/$E$18*$B$12 -> 96422.4 | C47: =(C45*$D$18)*DAY(EOMONTH(C$25,0))*1440/$E$18*$B$12 -> 285534.72 | D47: =(D45*$D$18)*DAY(EOMONTH(D$25,0))*1440/$E$18*$B$12 -> 505986.19 | E47: =(E45*$D$18)*DAY(EOMONTH(E$25,0))*1440/$E$18*$B$12 -> 730756.06 | F47: =(F45*$D$18)*DAY(EOMONTH(F$25,0))*1440/$E$18*$B$12 -> 877064.83 | G47: =(G45*$D$18)*DAY(EOMONTH(G$25,0))*1440/$E$18*$B$12 -> 1228655.9 | H47: =(H45*$D$18)*DAY(EOMONTH(H$25,0))*1440/$E$18*$B$12 -> 1457048.8 | I47: =(I45*$D$18)*DAY(EOMONTH(I$25,0))*1440/$E$18*$B$12 -> 1804110.5 | ... M47: =(M45*$D$18)*DAY(EOMONTH(M$25,0))*1440/$E$18*$B$12 -> 3159675
A48: Starter | AI diagnoses | B48: =(B45*$D$18)*Inputs!$B$8*$B$13*Inputs!$B$9*$F$18 -> 2.592 | C48: =(C45*$D$18)*Inputs!$B$8*$B$13*Inputs!$B$9*$F$18 -> 7.93152 | D48: =(D45*$D$18)*Inputs!$B$8*$B$13*Inputs!$B$9*$F$18 -> 13.601779 | E48: =(E45*$D$18)*Inputs!$B$8*$B$13*Inputs!$B$9*$F$18 -> 19.64398 | F48: =(F45*$D$18)*Inputs!$B$8*$B$13*Inputs!$B$9*$F$18 -> 26.10312 | G48: =(G45*$D$18)*Inputs!$B$8*$B$13*Inputs!$B$9*$F$18 -> 33.028384 | H48: =(H45*$D$18)*Inputs!$B$8*$B$13*Inputs!$B$9*$F$18 -> 40.473577 | I48: =(I45*$D$18)*Inputs!$B$8*$B$13*Inputs!$B$9*$F$18 -> 48.497595 | ... M48: =(M45*$D$18)*Inputs!$B$8*$B$13*Inputs!$B$9*$F$18 -> 87.768749
A49: Starter | Variable service expense | B49: =B47/1000*(Inputs!$B$19+Inputs!$B$20+Inputs!$B$21+Inputs!$B$22+Inputs!$B$23+Inputs!$B$24)+B48*((((Inputs!$B$10*Inputs!$B$15+Inputs!$B$11*Inputs!$B$16)*(1-Inputs!$B$14)+(Inputs!$B$10*Inputs!$B$17+Inputs!$B$11*Inputs!$B$18)*Inputs!$B$14)/1000000*Inputs!$B$12)*$B$11+Inputs!$B$12*Inputs!$B$13)+(B45*$D$18)*Inputs!$B$25*Inputs!$B$26+((B45*$D$18)*Inputs!$B$8*$B$13)*Inputs!$B$27*Inputs!$B$28+B46*(Inputs!$B$29+Inputs!$B$31)+B44*Inputs!$B$30+B45*Inputs!$B$32 -> 21.594793 | C49: =C47/1000*(Inputs!$B$19+Inputs!$B$20+Inputs!$B$21+Inputs!$B$22+Inputs!$B$23+Inputs!$B$24)+C48*((((Inputs!$B$10*Inputs!$B$15+Inputs!$B$11*Inputs!$B$16)*(1-Inputs!$B$14)+(Inputs!$B$10*Inputs!$B$17+Inputs!$B$11*Inputs!$B$18)*Inputs!$B$14)/1000000*Inputs!$B$12)*$B$11+Inputs!$B$12*Inputs!$B$13)+(C45*$D$18)*Inputs!$B$25*Inputs!$B$26+((C45*$D$18)*Inputs!$B$8*$B$13)*Inputs!$B$27*Inputs!$B$28+C46*(Inputs!$B$29+Inputs!$B$31)+C44*Inputs!$B$30+C45*Inputs!$B$32 -> 62.302036 | D49: =D47/1000*(Inputs!$B$19+Inputs!$B$20+Inputs!$B$21+Inputs!$B$22+Inputs!$B$23+Inputs!$B$24)+D48*((((Inputs!$B$10*Inputs!$B$15+Inputs!$B$11*Inputs!$B$16)*(1-Inputs!$B$14)+(Inputs!$B$10*Inputs!$B$17+Inputs!$B$11*Inputs!$B$18)*Inputs!$B$14)/1000000*Inputs!$B$12)*$B$11+Inputs!$B$12*Inputs!$B$13)+(D45*$D$18)*Inputs!$B$25*Inputs!$B$26+((D45*$D$18)*Inputs!$B$8*$B$13)*Inputs!$B$27*Inputs!$B$28+D46*(Inputs!$B$29+Inputs!$B$31)+D44*Inputs!$B$30+D45*Inputs!$B$32 -> 108.87124 | E49: =E47/1000*(Inputs!$B$19+Inputs!$B$20+Inputs!$B$21+Inputs!$B$22+Inputs!$B$23+Inputs!$B$24)+E48*((((Inputs!$B$10*Inputs!$B$15+Inputs!$B$11*Inputs!$B$16)*(1-Inputs!$B$14)+(Inputs!$B$10*Inputs!$B$17+Inputs!$B$11*Inputs!$B$18)*Inputs!$B$14)/1000000*Inputs!$B$12)*$B$11+Inputs!$B$12*Inputs!$B$13)+(E45*$D$18)*Inputs!$B$25*Inputs!$B$26+((E45*$D$18)*Inputs!$B$8*$B$13)*Inputs!$B$27*Inputs!$B$28+E46*(Inputs!$B$29+Inputs!$B$31)+E44*Inputs!$B$30+E45*Inputs!$B$32 -> 156.77516 | F49: =F47/1000*(Inputs!$B$19+Inputs!$B$20+Inputs!$B$21+Inputs!$B$22+Inputs!$B$23+Inputs!$B$24)+F48*((((Inputs!$B$10*Inputs!$B$15+Inputs!$B$11*Inputs!$B$16)*(1-Inputs!$B$14)+(Inputs!$B$10*Inputs!$B$17+Inputs!$B$11*Inputs!$B$18)*Inputs!$B$14)/1000000*Inputs!$B$12)*$B$11+Inputs!$B$12*Inputs!$B$13)+(F45*$D$18)*Inputs!$B$25*Inputs!$B$26+((F45*$D$18)*Inputs!$B$8*$B$13)*Inputs!$B$27*Inputs!$B$28+F46*(Inputs!$B$29+Inputs!$B$31)+F44*Inputs!$B$30+F45*Inputs!$B$32 -> 192.01369 | G49: =G47/1000*(Inputs!$B$19+Inputs!$B$20+Inputs!$B$21+Inputs!$B$22+Inputs!$B$23+Inputs!$B$24)+G48*((((Inputs!$B$10*Inputs!$B$15+Inputs!$B$11*Inputs!$B$16)*(1-Inputs!$B$14)+(Inputs!$B$10*Inputs!$B$17+Inputs!$B$11*Inputs!$B$18)*Inputs!$B$14)/1000000*Inputs!$B$12)*$B$11+Inputs!$B$12*Inputs!$B$13)+(G45*$D$18)*Inputs!$B$25*Inputs!$B$26+((G45*$D$18)*Inputs!$B$8*$B$13)*Inputs!$B$27*Inputs!$B$28+G46*(Inputs!$B$29+Inputs!$B$31)+G44*Inputs!$B$30+G45*Inputs!$B$32 -> 262.90235 | H49: =H47/1000*(Inputs!$B$19+Inputs!$B$20+Inputs!$B$21+Inputs!$B$22+Inputs!$B$23+Inputs!$B$24)+H48*((((Inputs!$B$10*Inputs!$B$15+Inputs!$B$11*Inputs!$B$16)*(1-Inputs!$B$14)+(Inputs!$B$10*Inputs!$B$17+Inputs!$B$11*Inputs!$B$18)*Inputs!$B$14)/1000000*Inputs!$B$12)*$B$11+Inputs!$B$12*Inputs!$B$13)+(H45*$D$18)*Inputs!$B$25*Inputs!$B$26+((H45*$D$18)*Inputs!$B$8*$B$13)*Inputs!$B$27*Inputs!$B$28+H46*(Inputs!$B$29+Inputs!$B$31)+H44*Inputs!$B$30+H45*Inputs!$B$32 -> 313.68607 | I49: =I47/1000*(Inputs!$B$19+Inputs!$B$20+Inputs!$B$21+Inputs!$B$22+Inputs!$B$23+Inputs!$B$24)+I48*((((Inputs!$B$10*Inputs!$B$15+Inputs!$B$11*Inputs!$B$16)*(1-Inputs!$B$14)+(Inputs!$B$10*Inputs!$B$17+Inputs!$B$11*Inputs!$B$18)*Inputs!$B$14)/1000000*Inputs!$B$12)*$B$11+Inputs!$B$12*Inputs!$B$13)+(I45*$D$18)*Inputs!$B$25*Inputs!$B$26+((I45*$D$18)*Inputs!$B$8*$B$13)*Inputs!$B$27*Inputs!$B$28+I46*(Inputs!$B$29+Inputs!$B$31)+I44*Inputs!$B$30+I45*Inputs!$B$32 -> 385.57704 | ... M49: =M47/1000*(Inputs!$B$19+Inputs!$B$20+Inputs!$B$21+Inputs!$B$22+Inputs!$B$23+Inputs!$B$24)+M48*((((Inputs!$B$10*Inputs!$B$15+Inputs!$B$11*Inputs!$B$16)*(1-Inputs!$B$14)+(Inputs!$B$10*Inputs!$B$17+Inputs!$B$11*Inputs!$B$18)*Inputs!$B$14)/1000000*Inputs!$B$12)*$B$11+Inputs!$B$12*Inputs!$B$13)+(M45*$D$18)*Inputs!$B$25*Inputs!$B$26+((M45*$D$18)*Inputs!$B$8*$B$13)*Inputs!$B$27*Inputs!$B$28+M46*(Inputs!$B$29+Inputs!$B$31)+M44*Inputs!$B$30+M45*Inputs!$B$32 -> 679.1527
A51: Pro | Opening accounts | B51: =0 -> 0 | C51: =B54 -> 3.6 | D51: =C54 -> 7.416 | E51: =D54 -> 11.47536 | F51: =E54 -> 15.807946 | G51: =F54 -> 20.446388 | H51: =G54 -> 25.426368 | I51: =H54 -> 30.786933 | J51: =I54 -> 36.570837 | ... M51: =L54 -> 56.95399
A52: Pro | New accounts | B52: =B27*$C$19 -> 3.6 | C52: =C27*$C$19 -> 3.96 | D52: =D27*$C$19 -> 4.356 | E52: =E27*$C$19 -> 4.7916 | F52: =F27*$C$19 -> 5.27076 | G52: =G27*$C$19 -> 5.797836 | H52: =H27*$C$19 -> 6.3776196 | I52: =I27*$C$19 -> 7.0153816 | ... M52: =M27*$C$19 -> 10.27122
A53: Pro | Churned accounts | B53: =B51*$B$7 -> 0 | C53: =C51*$B$7 -> 0.144 | D53: =D51*$B$7 -> 0.29664 | E53: =E51*$B$7 -> 0.4590144 | F53: =F51*$B$7 -> 0.63231782 | G53: =G51*$B$7 -> 0.81785551 | H53: =H51*$B$7 -> 1.0170547 | I53: =I51*$B$7 -> 1.2314773 | ... M53: =M51*$B$7 -> 2.2781596
...

Sheet Conservative
A1: Conservative — hypothetical 12-month forecast
A4: Initial monthly signups | B4: 80
A5: Monthly signup growth | B5: 0.05
A6: Paid conversion rate | B6: 0.04
A7: Monthly paid churn | B7: 0.07
A8: Monthly free churn | B8: 0.2
A9: Blended acquisition CAC | B9: 60
A10: Staff monthly budget | B10: =Inputs!$B$45 -> 3000
A11: AI cost stress multiplier | B11: =Inputs!$B$50 -> 1
A12: Monitoring frequency multiplier | B12: =Inputs!$B$51 -> 1
A13: Incident volume multiplier | B13: =Inputs!$B$52 -> 1
A17: Free | B17: =Pricing!B2 -> 0 | C17: =Pricing!C2 -> 0 | D17: =Pricing!D2 -> 1 | E17: =Pricing!E2 -> 15 | F17: =Pricing!F2 -> 0
A18: Starter | B18: =Pricing!B3 -> 9 | C18: 0.75 | D18: =Pricing!D3 -> 3 | E18: =Pricing!E3 -> 5 | F18: =Pricing!F3 -> 1
A19: Pro | B19: =Pricing!B4 -> 29 | C19: 0.22 | D19: =Pricing!D4 -> 10 | E19: =Pricing!E4 -> 5 | F19: =Pricing!F4 -> 1
A20: Business | B20: =Pricing!B5 -> 99 | C20: 0.03 | D20: =Pricing!D5 -> 30 | E20: =Pricing!E5 -> 5 | F20: =Pricing!F5 -> 1
B25: 46296 | C25: 46327 | D25: 46357 | E25: 46388 | F25: 46419 | G25: 46447 | H25: 46478 | I25: 46508 | J25: 46539 | K25: 46569 | L25: 46600 | M25: 46631
A26: New signups | B26: =$B$4 -> 80 | C26: =B26*(1+$B$5) -> 84 | D26: =C26*(1+$B$5) -> 88.2 | E26: =D26*(1+$B$5) -> 92.61 | F26: =E26*(1+$B$5) -> 97.2405 | G26: =F26*(1+$B$5) -> 102.10252 | H26: =G26*(1+$B$5) -> 107.20765 | I26: =H26*(1+$B$5) -> 112.56803 | J26: =I26*(1+$B$5) -> 118.19644 | ... M26: =L26*(1+$B$5) -> 136.82715
A27: New paid | B27: =B26*$B$6 -> 3.2 | C27: =C26*$B$6 -> 3.36 | D27: =D26*$B$6 -> 3.528 | E27: =E26*$B$6 -> 3.7044 | F27: =F26*$B$6 -> 3.88962 | G27: =G26*$B$6 -> 4.084101 | H27: =H26*$B$6 -> 4.2883061 | I27: =I26*$B$6 -> 4.5027214 | ... M27: =M26*$B$6 -> 5.4730859
A28: New free | B28: =B26-B27 -> 76.8 | C28: =C26-C27 -> 80.64 | D28: =D26-D27 -> 84.672 | E28: =E26-E27 -> 88.9056 | F28: =F26-F27 -> 93.35088 | G28: =G26-G27 -> 98.018424 | H28: =H26-H27 -> 102.91935 | I28: =I26-I27 -> 108.06531 | ... M28: =M26-M27 -> 131.35406
A31: Free | Opening accounts | B31: =0 -> 0 | C31: =B34 -> 76.8 | D31: =C34 -> 142.08 | E31: =D34 -> 198.336 | F31: =E34 -> 247.5744 | G31: =F34 -> 291.4104 | H31: =G34 -> 331.14674 | I31: =H34 -> 367.83674 | J31: =I34 -> 402.3347 | ... M31: =L34 -> 499.02797
A32: Free | New accounts | B32: =B28 -> 76.8 | C32: =C28 -> 80.64 | D32: =D28 -> 84.672 | E32: =E28 -> 88.9056 | F32: =F28 -> 93.35088 | G32: =G28 -> 98.018424 | H32: =H28 -> 102.91935 | I32: =I28 -> 108.06531 | ... M32: =M28 -> 131.35406
A33: Free | Churned accounts | B33: =B31*$B$8 -> 0 | C33: =C31*$B$8 -> 15.36 | D33: =D31*$B$8 -> 28.416 | E33: =E31*$B$8 -> 39.6672 | F33: =F31*$B$8 -> 49.51488 | G33: =G31*$B$8 -> 58.28208 | H33: =H31*$B$8 -> 66.229349 | I33: =I31*$B$8 -> 73.567348 | ... M33: =M31*$B$8 -> 99.805594
A34: Free | Ending accounts | B34: =B31+B32-B33 -> 76.8 | C34: =C31+C32-C33 -> 142.08 | D34: =D31+D32-D33 -> 198.336 | E34: =E31+E32-E33 -> 247.5744 | F34: =F31+F32-F33 -> 291.4104 | G34: =G31+G32-G33 -> 331.14674 | H34: =H31+H32-H33 -> 367.83674 | I34: =I31+I32-I33 -> 402.3347 | ... M34: =M31+M32-M33 -> 530.57644
A35: Free | Average accounts | B35: =(B31+B34)/2 -> 38.4 | C35: =(C31+C34)/2 -> 109.44 | D35: =(D31+D34)/2 -> 170.208 | E35: =(E31+E34)/2 -> 222.9552 | F35: =(F31+F34)/2 -> 269.4924 | G35: =(G31+G34)/2 -> 311.27857 | H35: =(H31+H34)/2 -> 349.49174 | I35: =(I31+I34)/2 -> 385.08572 | ... M35: =(M31+M34)/2 -> 514.80221
A36: Free | Revenue | B36: =B35*$B$17 -> 0 | C36: =C35*$B$17 -> 0 | D36: =D35*$B$17 -> 0 | E36: =E35*$B$17 -> 0 | F36: =F35*$B$17 -> 0 | G36: =G35*$B$17 -> 0 | H36: =H35*$B$17 -> 0 | I36: =I35*$B$17 -> 0 | ... M36: =M35*$B$17 -> 0
A37: Free | Monitoring checks | B37: =(B35*$D$17)*DAY(EOMONTH(B$25,0))*1440/$E$17*$B$12 -> 114278.4 | C37: =(C35*$D$17)*DAY(EOMONTH(C$25,0))*1440/$E$17*$B$12 -> 315187.2 | D37: =(D35*$D$17)*DAY(EOMONTH(D$25,0))*1440/$E$17*$B$12 -> 506539.01 | E37: =(E35*$D$17)*DAY(EOMONTH(E$25,0))*1440/$E$17*$B$12 -> 663514.68 | F37: =(F35*$D$17)*DAY(EOMONTH(F$25,0))*1440/$E$17*$B$12 -> 724395.57 | G37: =(G35*$D$17)*DAY(EOMONTH(G$25,0))*1440/$E$17*$B$12 -> 926365.03 | H37: =(H35*$D$17)*DAY(EOMONTH(H$25,0))*1440/$E$17*$B$12 -> 1006536.2 | I37: =(I35*$D$17)*DAY(EOMONTH(I$25,0))*1440/$E$17*$B$12 -> 1146015.1 | ... M37: =(M35*$D$17)*DAY(EOMONTH(M$25,0))*1440/$E$17*$B$12 -> 1482630.4
A38: Free | AI diagnoses | B38: =(B35*$D$17)*Inputs!$B$8*$B$13*Inputs!$B$9*$F$17 -> 0 | C38: =(C35*$D$17)*Inputs!$B$8*$B$13*Inputs!$B$9*$F$17 -> 0 | D38: =(D35*$D$17)*Inputs!$B$8*$B$13*Inputs!$B$9*$F$17 -> 0 | E38: =(E35*$D$17)*Inputs!$B$8*$B$13*Inputs!$B$9*$F$17 -> 0 | F38: =(F35*$D$17)*Inputs!$B$8*$B$13*Inputs!$B$9*$F$17 -> 0 | G38: =(G35*$D$17)*Inputs!$B$8*$B$13*Inputs!$B$9*$F$17 -> 0 | H38: =(H35*$D$17)*Inputs!$B$8*$B$13*Inputs!$B$9*$F$17 -> 0 | I38: =(I35*$D$17)*Inputs!$B$8*$B$13*Inputs!$B$9*$F$17 -> 0 | ... M38: =(M35*$D$17)*Inputs!$B$8*$B$13*Inputs!$B$9*$F$17 -> 0
A39: Free | Variable service expense | B39: =B37/1000*(Inputs!$B$19+Inputs!$B$20+Inputs!$B$21+Inputs!$B$22+Inputs!$B$23+Inputs!$B$24)+B38*((((Inputs!$B$10*Inputs!$B$15+Inputs!$B$11*Inputs!$B$16)*(1-Inputs!$B$14)+(Inputs!$B$10*Inputs!$B$17+Inputs!$B$11*Inputs!$B$18)*Inputs!$B$14)/1000000*Inputs!$B$12)*$B$11+Inputs!$B$12*Inputs!$B$13)+(B35*$D$17)*Inputs!$B$25*Inputs!$B$26+((B35*$D$17)*Inputs!$B$8*$B$13)*Inputs!$B$27*Inputs!$B$28+B36*(Inputs!$B$29+Inputs!$B$31) -> 19.534848 | C39: =C37/1000*(Inputs!$B$19+Inputs!$B$20+Inputs!$B$21+Inputs!$B$22+Inputs!$B$23+Inputs!$B$24)+C38*((((Inputs!$B$10*Inputs!$B$15+Inputs!$B$11*Inputs!$B$16)*(1-Inputs!$B$14)+(Inputs!$B$10*Inputs!$B$17+Inputs!$B$11*Inputs!$B$18)*Inputs!$B$14)/1000000*Inputs!$B$12)*$B$11+Inputs!$B$12*Inputs!$B$13)+(C35*$D$17)*Inputs!$B$25*Inputs!$B$26+((C35*$D$17)*Inputs!$B$8*$B$13)*Inputs!$B$27*Inputs!$B$28+C36*(Inputs!$B$29+Inputs!$B$31) -> 53.888256 | D39: =D37/1000*(Inputs!$B$19+Inputs!$B$20+Inputs!$B$21+Inputs!$B$22+Inputs!$B$23+Inputs!$B$24)+D38*((((Inputs!$B$10*Inputs!$B$15+Inputs!$B$11*Inputs!$B$16)*(1-Inputs!$B$14)+(Inputs!$B$10*Inputs!$B$17+Inputs!$B$11*Inputs!$B$18)*Inputs!$B$14)/1000000*Inputs!$B$12)*$B$11+Inputs!$B$12*Inputs!$B$13)+(D35*$D$17)*Inputs!$B$25*Inputs!$B$26+((D35*$D$17)*Inputs!$B$8*$B$13)*Inputs!$B$27*Inputs!$B$28+D36*(Inputs!$B$29+Inputs!$B$31) -> 86.588214 | E39: =E37/1000*(Inputs!$B$19+Inputs!$B$20+Inputs!$B$21+Inputs!$B$22+Inputs!$B$23+Inputs!$B$24)+E38*((((Inputs!$B$10*Inputs!$B$15+Inputs!$B$11*Inputs!$B$16)*(1-Inputs!$B$14)+(Inputs!$B$10*Inputs!$B$17+Inputs!$B$11*Inputs!$B$18)*Inputs!$B$14)/1000000*Inputs!$B$12)*$B$11+Inputs!$B$12*Inputs!$B$13)+(E35*$D$17)*Inputs!$B$25*Inputs!$B$26+((E35*$D$17)*Inputs!$B$8*$B$13)*Inputs!$B$27*Inputs!$B$28+E36*(Inputs!$B$29+Inputs!$B$31) -> 113.42177 | F39: =F37/1000*(Inputs!$B$19+Inputs!$B$20+Inputs!$B$21+Inputs!$B$22+Inputs!$B$23+Inputs!$B$24)+F38*((((Inputs!$B$10*Inputs!$B$15+Inputs!$B$11*Inputs!$B$16)*(1-Inputs!$B$14)+(Inputs!$B$10*Inputs!$B$17+Inputs!$B$11*Inputs!$B$18)*Inputs!$B$14)/1000000*Inputs!$B$12)*$B$11+Inputs!$B$12*Inputs!$B$13)+(F35*$D$17)*Inputs!$B$25*Inputs!$B$26+((F35*$D$17)*Inputs!$B$8*$B$13)*Inputs!$B$27*Inputs!$B$28+F36*(Inputs!$B$29+Inputs!$B$31) -> 123.90183 | G39: =G37/1000*(Inputs!$B$19+Inputs!$B$20+Inputs!$B$21+Inputs!$B$22+Inputs!$B$23+Inputs!$B$24)+G38*((((Inputs!$B$10*Inputs!$B$15+Inputs!$B$11*Inputs!$B$16)*(1-Inputs!$B$14)+(Inputs!$B$10*Inputs!$B$17+Inputs!$B$11*Inputs!$B$18)*Inputs!$B$14)/1000000*Inputs!$B$12)*$B$11+Inputs!$B$12*Inputs!$B$13)+(G35*$D$17)*Inputs!$B$25*Inputs!$B$26+((G35*$D$17)*Inputs!$B$8*$B$13)*Inputs!$B$27*Inputs!$B$28+G36*(Inputs!$B$29+Inputs!$B$31) -> 158.35364 | H39: =H37/1000*(Inputs!$B$19+Inputs!$B$20+Inputs!$B$21+Inputs!$B$22+Inputs!$B$23+Inputs!$B$24)+H38*((((Inputs!$B$10*Inputs!$B$15+Inputs!$B$11*Inputs!$B$16)*(1-Inputs!$B$14)+(Inputs!$B$10*Inputs!$B$17+Inputs!$B$11*Inputs!$B$18)*Inputs!$B$14)/1000000*Inputs!$B$12)*$B$11+Inputs!$B$12*Inputs!$B$13)+(H35*$D$17)*Inputs!$B$25*Inputs!$B$26+((H35*$D$17)*Inputs!$B$8*$B$13)*Inputs!$B$27*Inputs!$B$28+H36*(Inputs!$B$29+Inputs!$B$31) -> 172.08973 | I39: =I37/1000*(Inputs!$B$19+Inputs!$B$20+Inputs!$B$21+Inputs!$B$22+Inputs!$B$23+Inputs!$B$24)+I38*((((Inputs!$B$10*Inputs!$B$15+Inputs!$B$11*Inputs!$B$16)*(1-Inputs!$B$14)+(Inputs!$B$10*Inputs!$B$17+Inputs!$B$11*Inputs!$B$18)*Inputs!$B$14)/1000000*Inputs!$B$12)*$B$11+Inputs!$B$12*Inputs!$B$13)+(I35*$D$17)*Inputs!$B$25*Inputs!$B$26+((I35*$D$17)*Inputs!$B$8*$B$13)*Inputs!$B$27*Inputs!$B$28+I36*(Inputs!$B$29+Inputs!$B$31) -> 195.90081 | ... M39: =M37/1000*(Inputs!$B$19+Inputs!$B$20+Inputs!$B$21+Inputs!$B$22+Inputs!$B$23+Inputs!$B$24)+M38*((((Inputs!$B$10*Inputs!$B$15+Inputs!$B$11*Inputs!$B$16)*(1-Inputs!$B$14)+(Inputs!$B$10*Inputs!$B$17+Inputs!$B$11*Inputs!$B$18)*Inputs!$B$14)/1000000*Inputs!$B$12)*$B$11+Inputs!$B$12*Inputs!$B$13)+(M35*$D$17)*Inputs!$B$25*Inputs!$B$26+((M35*$D$17)*Inputs!$B$8*$B$13)*Inputs!$B$27*Inputs!$B$28+M36*(Inputs!$B$29+Inputs!$B$31) -> 253.48861
A41: Starter | Opening accounts | B41: =0 -> 0 | C41: =B44 -> 2.4 | D41: =C44 -> 4.752 | E41: =D44 -> 7.06536 | F41: =E44 -> 9.3490848 | G41: =F44 -> 11.611864 | H41: =G44 -> 13.862109 | I41: =H44 -> 16.107991 | J41: =I44 -> 18.357473 | ... M41: =L44 -> 25.204716
A42: Starter | New accounts | B42: =B27*$C$18 -> 2.4 | C42: =C27*$C$18 -> 2.52 | D42: =D27*$C$18 -> 2.646 | E42: =E27*$C$18 -> 2.7783 | F42: =F27*$C$18 -> 2.917215 | G42: =G27*$C$18 -> 3.0630757 | H42: =H27*$C$18 -> 3.2162295 | I42: =I27*$C$18 -> 3.377041 | ... M42: =M27*$C$18 -> 4.1048145
A43: Starter | Churned accounts | B43: =B41*$B$7 -> 0 | C43: =C41*$B$7 -> 0.168 | D43: =D41*$B$7 -> 0.33264 | E43: =E41*$B$7 -> 0.4945752 | F43: =F41*$B$7 -> 0.65443594 | G43: =G41*$B$7 -> 0.81283047 | H43: =H41*$B$7 -> 0.97034764 | I43: =I41*$B$7 -> 1.1275594 | ... M43: =M41*$B$7 -> 1.7643301
A44: Starter | Ending accounts | B44: =B41+B42-B43 -> 2.4 | C44: =C41+C42-C43 -> 4.752 | D44: =D41+D42-D43 -> 7.06536 | E44: =E41+E42-E43 -> 9.3490848 | F44: =F41+F42-F43 -> 11.611864 | G44: =G41+G42-G43 -> 13.862109 | H44: =H41+H42-H43 -> 16.107991 | I44: =I41+I42-I43 -> 18.357473 | ... M44: =M41+M42-M43 -> 27.545201
A45: Starter | Average accounts | B45: =(B41+B44)/2 -> 1.2 | C45: =(C41+C44)/2 -> 3.576 | D45: =(D41+D44)/2 -> 5.90868 | E45: =(E41+E44)/2 -> 8.2072224 | F45: =(F41+F44)/2 -> 10.480474 | G45: =(G41+G44)/2 -> 12.736987 | H45: =(H41+H44)/2 -> 14.98505 | I45: =(I41+I44)/2 -> 17.232732 | ... M45: =(M41+M44)/2 -> 26.374958
A46: Starter | Revenue | B46: =B45*$B$18 -> 10.8 | C46: =C45*$B$18 -> 32.184 | D46: =D45*$B$18 -> 53.17812 | E46: =E45*$B$18 -> 73.865002 | F46: =F45*$B$18 -> 94.324269 | G46: =G45*$B$18 -> 114.63288 | H46: =H45*$B$18 -> 134.86545 | I46: =I45*$B$18 -> 155.09459 | ... M46: =M45*$B$18 -> 237.37463
A47: Starter | Monitoring checks | B47: =(B45*$D$18)*DAY(EOMONTH(B$25,0))*1440/$E$18*$B$12 -> 32140.8 | C47: =(C45*$D$18)*DAY(EOMONTH(C$25,0))*1440/$E$18*$B$12 -> 92689.92 | D47: =(D45*$D$18)*DAY(EOMONTH(D$25,0))*1440/$E$18*$B$12 -> 158258.09 | E47: =(E45*$D$18)*DAY(EOMONTH(E$25,0))*1440/$E$18*$B$12 -> 219822.24 | F47: =(F45*$D$18)*DAY(EOMONTH(F$25,0))*1440/$E$18*$B$12 -> 253543.64 | G47: =(G45*$D$18)*DAY(EOMONTH(G$25,0))*1440/$E$18*$B$12 -> 341147.45 | H47: =(H45*$D$18)*DAY(EOMONTH(H$25,0))*1440/$E$18*$B$12 -> 388412.5 | I47: =(I45*$D$18)*DAY(EOMONTH(I$25,0))*1440/$E$18*$B$12 -> 461561.49 | ... M47: =(M45*$D$18)*DAY(EOMONTH(M$25,0))*1440/$E$18*$B$12 -> 683638.92
A48: Starter | AI diagnoses | B48: =(B45*$D$18)*Inputs!$B$8*$B$13*Inputs!$B$9*$F$18 -> 0.864 | C48: =(C45*$D$18)*Inputs!$B$8*$B$13*Inputs!$B$9*$F$18 -> 2.57472 | D48: =(D45*$D$18)*Inputs!$B$8*$B$13*Inputs!$B$9*$F$18 -> 4.2542496 | E48: =(E45*$D$18)*Inputs!$B$8*$B$13*Inputs!$B$9*$F$18 -> 5.9092001 | F48: =(F45*$D$18)*Inputs!$B$8*$B$13*Inputs!$B$9*$F$18 -> 7.5459415 | G48: =(G45*$D$18)*Inputs!$B$8*$B$13*Inputs!$B$9*$F$18 -> 9.1706303 | H48: =(H45*$D$18)*Inputs!$B$8*$B$13*Inputs!$B$9*$F$18 -> 10.789236 | I48: =(I45*$D$18)*Inputs!$B$8*$B$13*Inputs!$B$9*$F$18 -> 12.407567 | ... M48: =(M45*$D$18)*Inputs!$B$8*$B$13*Inputs!$B$9*$F$18 -> 18.98997
A49: Starter | Variable service expense | B49: =B47/1000*(Inputs!$B$19+Inputs!$B$20+Inputs!$B$21+Inputs!$B$22+Inputs!$B$23+Inputs!$B$24)+B48*((((Inputs!$B$10*Inputs!$B$15+Inputs!$B$11*Inputs!$B$16)*(1-Inputs!$B$14)+(Inputs!$B$10*Inputs!$B$17+Inputs!$B$11*Inputs!$B$18)*Inputs!$B$14)/1000000*Inputs!$B$12)*$B$11+Inputs!$B$12*Inputs!$B$13)+(B45*$D$18)*Inputs!$B$25*Inputs!$B$26+((B45*$D$18)*Inputs!$B$8*$B$13)*Inputs!$B$27*Inputs!$B$28+B46*(Inputs!$B$29+Inputs!$B$31)+B44*Inputs!$B$30+B45*Inputs!$B$32 -> 7.1982643 | C49: =C47/1000*(Inputs!$B$19+Inputs!$B$20+Inputs!$B$21+Inputs!$B$22+Inputs!$B$23+Inputs!$B$24)+C48*((((Inputs!$B$10*Inputs!$B$15+Inputs!$B$11*Inputs!$B$16)*(1-Inputs!$B$14)+(Inputs!$B$10*Inputs!$B$17+Inputs!$B$11*Inputs!$B$18)*Inputs!$B$14)/1000000*Inputs!$B$12)*$B$11+Inputs!$B$12*Inputs!$B$13)+(C45*$D$18)*Inputs!$B$25*Inputs!$B$26+((C45*$D$18)*Inputs!$B$8*$B$13)*Inputs!$B$27*Inputs!$B$28+C46*(Inputs!$B$29+Inputs!$B$31)+C44*Inputs!$B$30+C45*Inputs!$B$32 -> 20.205585 | D49: =D47/1000*(Inputs!$B$19+Inputs!$B$20+Inputs!$B$21+Inputs!$B$22+Inputs!$B$23+Inputs!$B$24)+D48*((((Inputs!$B$10*Inputs!$B$15+Inputs!$B$11*Inputs!$B$16)*(1-Inputs!$B$14)+(Inputs!$B$10*Inputs!$B$17+Inputs!$B$11*Inputs!$B$18)*Inputs!$B$14)/1000000*Inputs!$B$12)*$B$11+Inputs!$B$12*Inputs!$B$13)+(D45*$D$18)*Inputs!$B$25*Inputs!$B$26+((D45*$D$18)*Inputs!$B$8*$B$13)*Inputs!$B$27*Inputs!$B$28+D46*(Inputs!$B$29+Inputs!$B$31)+D44*Inputs!$B$30+D45*Inputs!$B$32 -> 34.017934 | E49: =E47/1000*(Inputs!$B$19+Inputs!$B$20+Inputs!$B$21+Inputs!$B$22+Inputs!$B$23+Inputs!$B$24)+E48*((((Inputs!$B$10*Inputs!$B$15+Inputs!$B$11*Inputs!$B$16)*(1-Inputs!$B$14)+(Inputs!$B$10*Inputs!$B$17+Inputs!$B$11*Inputs!$B$18)*Inputs!$B$14)/1000000*Inputs!$B$12)*$B$11+Inputs!$B$12*Inputs!$B$13)+(E45*$D$18)*Inputs!$B$25*Inputs!$B$26+((E45*$D$18)*Inputs!$B$8*$B$13)*Inputs!$B$27*Inputs!$B$28+E46*(Inputs!$B$29+Inputs!$B$31)+E44*Inputs!$B$30+E45*Inputs!$B$32 -> 47.111855 | F49: =F47/1000*(Inputs!$B$19+Inputs!$B$20+Inputs!$B$21+Inputs!$B$22+Inputs!$B$23+Inputs!$B$24)+F48*((((Inputs!$B$10*Inputs!$B$15+Inputs!$B$11*Inputs!$B$16)*(1-Inputs!$B$14)+(Inputs!$B$10*Inputs!$B$17+Inputs!$B$11*Inputs!$B$18)*Inputs!$B$14)/1000000*Inputs!$B$12)*$B$11+Inputs!$B$12*Inputs!$B$13)+(F45*$D$18)*Inputs!$B$25*Inputs!$B$26+((F45*$D$18)*Inputs!$B$8*$B$13)*Inputs!$B$27*Inputs!$B$28+F46*(Inputs!$B$29+Inputs!$B$31)+F44*Inputs!$B$30+F45*Inputs!$B$32 -> 55.444845 | G49: =G47/1000*(Inputs!$B$19+Inputs!$B$20+Inputs!$B$21+Inputs!$B$22+Inputs!$B$23+Inputs!$B$24)+G48*((((Inputs!$B$10*Inputs!$B$15+Inputs!$B$11*Inputs!$B$16)*(1-Inputs!$B$14)+(Inputs!$B$10*Inputs!$B$17+Inputs!$B$11*Inputs!$B$18)*Inputs!$B$14)/1000000*Inputs!$B$12)*$B$11+Inputs!$B$12*Inputs!$B$13)+(G45*$D$18)*Inputs!$B$25*Inputs!$B$26+((G45*$D$18)*Inputs!$B$8*$B$13)*Inputs!$B$27*Inputs!$B$28+G46*(Inputs!$B$29+Inputs!$B$31)+G44*Inputs!$B$30+G45*Inputs!$B$32 -> 72.919937 | H49: =H47/1000*(Inputs!$B$19+Inputs!$B$20+Inputs!$B$21+Inputs!$B$22+Inputs!$B$23+Inputs!$B$24)+H48*((((Inputs!$B$10*Inputs!$B$15+Inputs!$B$11*Inputs!$B$16)*(1-Inputs!$B$14)+(Inputs!$B$10*Inputs!$B$17+Inputs!$B$11*Inputs!$B$18)*Inputs!$B$14)/1000000*Inputs!$B$12)*$B$11+Inputs!$B$12*Inputs!$B$13)+(H45*$D$18)*Inputs!$B$25*Inputs!$B$26+((H45*$D$18)*Inputs!$B$8*$B$13)*Inputs!$B$27*Inputs!$B$28+H46*(Inputs!$B$29+Inputs!$B$31)+H44*Inputs!$B$30+H45*Inputs!$B$32 -> 83.528989 | I49: =I47/1000*(Inputs!$B$19+Inputs!$B$20+Inputs!$B$21+Inputs!$B$22+Inputs!$B$23+Inputs!$B$24)+I48*((((Inputs!$B$10*Inputs!$B$15+Inputs!$B$11*Inputs!$B$16)*(1-Inputs!$B$14)+(Inputs!$B$10*Inputs!$B$17+Inputs!$B$11*Inputs!$B$18)*Inputs!$B$14)/1000000*Inputs!$B$12)*$B$11+Inputs!$B$12*Inputs!$B$13)+(I45*$D$18)*Inputs!$B$25*Inputs!$B$26+((I45*$D$18)*Inputs!$B$8*$B$13)*Inputs!$B$27*Inputs!$B$28+I46*(Inputs!$B$29+Inputs!$B$31)+I44*Inputs!$B$30+I45*Inputs!$B$32 -> 98.539068 | ... M49: =M47/1000*(Inputs!$B$19+Inputs!$B$20+Inputs!$B$21+Inputs!$B$22+Inputs!$B$23+Inputs!$B$24)+M48*((((Inputs!$B$10*Inputs!$B$15+Inputs!$B$11*Inputs!$B$16)*(1-Inputs!$B$14)+(Inputs!$B$10*Inputs!$B$17+Inputs!$B$11*Inputs!$B$18)*Inputs!$B$14)/1000000*Inputs!$B$12)*$B$11+Inputs!$B$12*Inputs!$B$13)+(M45*$D$18)*Inputs!$B$25*Inputs!$B$26+((M45*$D$18)*Inputs!$B$8*$B$13)*Inputs!$B$27*Inputs!$B$28+M46*(Inputs!$B$29+Inputs!$B$31)+M44*Inputs!$B$30+M45*Inputs!$B$32 -> 146.77623
A51: Pro | Opening accounts | B51: =0 -> 0 | C51: =B54 -> 0.704 | D51: =C54 -> 1.39392 | E51: =D54 -> 2.0725056 | F51: =E54 -> 2.7423982 | G51: =F54 -> 3.4061467 | H51: =G54 -> 4.0662187 | I51: =H54 -> 4.7250107 | J51: =I54 -> 5.3848587 | ... M51: =L54 -> 7.3933834
A52: Pro | New accounts | B52: =B27*$C$19 -> 0.704 | C52: =C27*$C$19 -> 0.7392 | D52: =D27*$C$19 -> 0.77616 | E52: =E27*$C$19 -> 0.814968 | F52: =F27*$C$19 -> 0.8557164 | G52: =G27*$C$19 -> 0.89850222 | H52: =H27*$C$19 -> 0.94342733 | I52: =I27*$C$19 -> 0.9905987 | ... M52: =M27*$C$19 -> 1.2040789
A53: Pro | Churned accounts | B53: =B51*$B$7 -> 0 | C53: =C51*$B$7 -> 0.04928 | D53: =D51*$B$7 -> 0.0975744 | E53: =E51*$B$7 -> 0.14507539 | F53: =F51*$B$7 -> 0.19196787 | G53: =G51*$B$7 -> 0.23843027 | H53: =H51*$B$7 -> 0.28463531 | I53: =I51*$B$7 -> 0.33075075 | ... M53: =M51*$B$7 -> 0.51753684
...

Sheet Optimistic
A1: Optimistic — hypothetical 12-month forecast
A4: Initial monthly signups | B4: 300
A5: Monthly signup growth | B5: 0.15
A6: Paid conversion rate | B6: 0.12
A7: Monthly paid churn | B7: 0.025
A8: Monthly free churn | B8: 0.1
A9: Blended acquisition CAC | B9: 30
A10: Staff monthly budget | B10: =Inputs!$B$45 -> 3000
A11: AI cost stress multiplier | B11: =Inputs!$B$50 -> 1
A12: Monitoring frequency multiplier | B12: =Inputs!$B$51 -> 1
A13: Incident volume multiplier | B13: =Inputs!$B$52 -> 1
A17: Free | B17: =Pricing!B2 -> 0 | C17: =Pricing!C2 -> 0 | D17: =Pricing!D2 -> 1 | E17: =Pricing!E2 -> 15 | F17: =Pricing!F2 -> 0
A18: Starter | B18: =Pricing!B3 -> 9 | C18: 0.45 | D18: =Pricing!D3 -> 3 | E18: =Pricing!E3 -> 5 | F18: =Pricing!F3 -> 1
A19: Pro | B19: =Pricing!B4 -> 29 | C19: 0.4 | D19: =Pricing!D4 -> 10 | E19: =Pricing!E4 -> 5 | F19: =Pricing!F4 -> 1
A20: Business | B20: =Pricing!B5 -> 99 | C20: 0.15 | D20: =Pricing!D5 -> 30 | E20: =Pricing!E5 -> 5 | F20: =Pricing!F5 -> 1
B25: 46296 | C25: 46327 | D25: 46357 | E25: 46388 | F25: 46419 | G25: 46447 | H25: 46478 | I25: 46508 | J25: 46539 | K25: 46569 | L25: 46600 | M25: 46631
A26: New signups | B26: =$B$4 -> 300 | C26: =B26*(1+$B$5) -> 345 | D26: =C26*(1+$B$5) -> 396.75 | E26: =D26*(1+$B$5) -> 456.2625 | F26: =E26*(1+$B$5) -> 524.70187 | G26: =F26*(1+$B$5) -> 603.40716 | H26: =G26*(1+$B$5) -> 693.91823 | I26: =H26*(1+$B$5) -> 798.00596 | J26: =I26*(1+$B$5) -> 917.70686 | ... M26: =L26*(1+$B$5) -> 1395.7174
A27: New paid | B27: =B26*$B$6 -> 36 | C27: =C26*$B$6 -> 41.4 | D27: =D26*$B$6 -> 47.61 | E27: =E26*$B$6 -> 54.7515 | F27: =F26*$B$6 -> 62.964225 | G27: =G26*$B$6 -> 72.408859 | H27: =H26*$B$6 -> 83.270188 | I27: =I26*$B$6 -> 95.760716 | ... M27: =M26*$B$6 -> 167.48609
A28: New free | B28: =B26-B27 -> 264 | C28: =C26-C27 -> 303.6 | D28: =D26-D27 -> 349.14 | E28: =E26-E27 -> 401.511 | F28: =F26-F27 -> 461.73765 | G28: =G26-G27 -> 530.9983 | H28: =H26-H27 -> 610.64804 | I28: =I26-I27 -> 702.24525 | ... M28: =M26-M27 -> 1228.2313
A31: Free | Opening accounts | B31: =0 -> 0 | C31: =B34 -> 264 | D31: =C34 -> 541.2 | E31: =D34 -> 836.22 | F31: =E34 -> 1154.109 | G31: =F34 -> 1500.4358 | H31: =G34 -> 1881.3905 | I31: =H34 -> 2303.8995 | J31: =I34 -> 2775.7548 | ... M31: =L34 -> 4581.5413
A32: Free | New accounts | B32: =B28 -> 264 | C32: =C28 -> 303.6 | D32: =D28 -> 349.14 | E32: =E28 -> 401.511 | F32: =F28 -> 461.73765 | G32: =G28 -> 530.9983 | H32: =H28 -> 610.64804 | I32: =I28 -> 702.24525 | ... M32: =M28 -> 1228.2313
A33: Free | Churned accounts | B33: =B31*$B$8 -> 0 | C33: =C31*$B$8 -> 26.4 | D33: =D31*$B$8 -> 54.12 | E33: =E31*$B$8 -> 83.622 | F33: =F31*$B$8 -> 115.4109 | G33: =G31*$B$8 -> 150.04358 | H33: =H31*$B$8 -> 188.13905 | I33: =I31*$B$8 -> 230.38995 | ... M33: =M31*$B$8 -> 458.15413
A34: Free | Ending accounts | B34: =B31+B32-B33 -> 264 | C34: =C31+C32-C33 -> 541.2 | D34: =D31+D32-D33 -> 836.22 | E34: =E31+E32-E33 -> 1154.109 | F34: =F31+F32-F33 -> 1500.4358 | G34: =G31+G32-G33 -> 1881.3905 | H34: =H31+H32-H33 -> 2303.8995 | I34: =I31+I32-I33 -> 2775.7548 | ... M34: =M31+M32-M33 -> 5351.6185
A35: Free | Average accounts | B35: =(B31+B34)/2 -> 132 | C35: =(C31+C34)/2 -> 402.6 | D35: =(D31+D34)/2 -> 688.71 | E35: =(E31+E34)/2 -> 995.1645 | F35: =(F31+F34)/2 -> 1327.2724 | G35: =(G31+G34)/2 -> 1690.9131 | H35: =(H31+H34)/2 -> 2092.645 | I35: =(I31+I34)/2 -> 2539.8271 | ... M35: =(M31+M34)/2 -> 4966.5799
A36: Free | Revenue | B36: =B35*$B$17 -> 0 | C36: =C35*$B$17 -> 0 | D36: =D35*$B$17 -> 0 | E36: =E35*$B$17 -> 0 | F36: =F35*$B$17 -> 0 | G36: =G35*$B$17 -> 0 | H36: =H35*$B$17 -> 0 | I36: =I35*$B$17 -> 0 | ... M36: =M35*$B$17 -> 0
A37: Free | Monitoring checks | B37: =(B35*$D$17)*DAY(EOMONTH(B$25,0))*1440/$E$17*$B$12 -> 392832 | C37: =(C35*$D$17)*DAY(EOMONTH(C$25,0))*1440/$E$17*$B$12 -> 1159488 | D37: =(D35*$D$17)*DAY(EOMONTH(D$25,0))*1440/$E$17*$B$12 -> 2049601 | E37: =(E35*$D$17)*DAY(EOMONTH(E$25,0))*1440/$E$17*$B$12 -> 2961609.6 | F37: =(F35*$D$17)*DAY(EOMONTH(F$25,0))*1440/$E$17*$B$12 -> 3567708.1 | G37: =(G35*$D$17)*DAY(EOMONTH(G$25,0))*1440/$E$17*$B$12 -> 5032157.4 | H37: =(H35*$D$17)*DAY(EOMONTH(H$25,0))*1440/$E$17*$B$12 -> 6026817.5 | I37: =(I35*$D$17)*DAY(EOMONTH(I$25,0))*1440/$E$17*$B$12 -> 7558525.5 | ... M37: =(M35*$D$17)*DAY(EOMONTH(M$25,0))*1440/$E$17*$B$12 -> 14303750
A38: Free | AI diagnoses | B38: =(B35*$D$17)*Inputs!$B$8*$B$13*Inputs!$B$9*$F$17 -> 0 | C38: =(C35*$D$17)*Inputs!$B$8*$B$13*Inputs!$B$9*$F$17 -> 0 | D38: =(D35*$D$17)*Inputs!$B$8*$B$13*Inputs!$B$9*$F$17 -> 0 | E38: =(E35*$D$17)*Inputs!$B$8*$B$13*Inputs!$B$9*$F$17 -> 0 | F38: =(F35*$D$17)*Inputs!$B$8*$B$13*Inputs!$B$9*$F$17 -> 0 | G38: =(G35*$D$17)*Inputs!$B$8*$B$13*Inputs!$B$9*$F$17 -> 0 | H38: =(H35*$D$17)*Inputs!$B$8*$B$13*Inputs!$B$9*$F$17 -> 0 | I38: =(I35*$D$17)*Inputs!$B$8*$B$13*Inputs!$B$9*$F$17 -> 0 | ... M38: =(M35*$D$17)*Inputs!$B$8*$B$13*Inputs!$B$9*$F$17 -> 0
A39: Free | Variable service expense | B39: =B37/1000*(Inputs!$B$19+Inputs!$B$20+Inputs!$B$21+Inputs!$B$22+Inputs!$B$23+Inputs!$B$24)+B38*((((Inputs!$B$10*Inputs!$B$15+Inputs!$B$11*Inputs!$B$16)*(1-Inputs!$B$14)+(Inputs!$B$10*Inputs!$B$17+Inputs!$B$11*Inputs!$B$18)*Inputs!$B$14)/1000000*Inputs!$B$12)*$B$11+Inputs!$B$12*Inputs!$B$13)+(B35*$D$17)*Inputs!$B$25*Inputs!$B$26+((B35*$D$17)*Inputs!$B$8*$B$13)*Inputs!$B$27*Inputs!$B$28+B36*(Inputs!$B$29+Inputs!$B$31) -> 67.15104 | C39: =C37/1000*(Inputs!$B$19+Inputs!$B$20+Inputs!$B$21+Inputs!$B$22+Inputs!$B$23+Inputs!$B$24)+C38*((((Inputs!$B$10*Inputs!$B$15+Inputs!$B$11*Inputs!$B$16)*(1-Inputs!$B$14)+(Inputs!$B$10*Inputs!$B$17+Inputs!$B$11*Inputs!$B$18)*Inputs!$B$14)/1000000*Inputs!$B$12)*$B$11+Inputs!$B$12*Inputs!$B$13)+(C35*$D$17)*Inputs!$B$25*Inputs!$B$26+((C35*$D$17)*Inputs!$B$8*$B$13)*Inputs!$B$27*Inputs!$B$28+C36*(Inputs!$B$29+Inputs!$B$31) -> 198.24024 | D39: =D37/1000*(Inputs!$B$19+Inputs!$B$20+Inputs!$B$21+Inputs!$B$22+Inputs!$B$23+Inputs!$B$24)+D38*((((Inputs!$B$10*Inputs!$B$15+Inputs!$B$11*Inputs!$B$16)*(1-Inputs!$B$14)+(Inputs!$B$10*Inputs!$B$17+Inputs!$B$11*Inputs!$B$18)*Inputs!$B$14)/1000000*Inputs!$B$12)*$B$11+Inputs!$B$12*Inputs!$B$13)+(D35*$D$17)*Inputs!$B$25*Inputs!$B$26+((D35*$D$17)*Inputs!$B$8*$B$13)*Inputs!$B$27*Inputs!$B$28+D36*(Inputs!$B$29+Inputs!$B$31) -> 350.36055 | E39: =E37/1000*(Inputs!$B$19+Inputs!$B$20+Inputs!$B$21+Inputs!$B$22+Inputs!$B$23+Inputs!$B$24)+E38*((((Inputs!$B$10*Inputs!$B$15+Inputs!$B$11*Inputs!$B$16)*(1-Inputs!$B$14)+(Inputs!$B$10*Inputs!$B$17+Inputs!$B$11*Inputs!$B$18)*Inputs!$B$14)/1000000*Inputs!$B$12)*$B$11+Inputs!$B$12*Inputs!$B$13)+(E35*$D$17)*Inputs!$B$25*Inputs!$B$26+((E35*$D$17)*Inputs!$B$8*$B$13)*Inputs!$B$27*Inputs!$B$28+E36*(Inputs!$B$29+Inputs!$B$31) -> 506.26008 | F39: =F37/1000*(Inputs!$B$19+Inputs!$B$20+Inputs!$B$21+Inputs!$B$22+Inputs!$B$23+Inputs!$B$24)+F38*((((Inputs!$B$10*Inputs!$B$15+Inputs!$B$11*Inputs!$B$16)*(1-Inputs!$B$14)+(Inputs!$B$10*Inputs!$B$17+Inputs!$B$11*Inputs!$B$18)*Inputs!$B$14)/1000000*Inputs!$B$12)*$B$11+Inputs!$B$12*Inputs!$B$13)+(F35*$D$17)*Inputs!$B$25*Inputs!$B$26+((F35*$D$17)*Inputs!$B$8*$B$13)*Inputs!$B$27*Inputs!$B$28+F36*(Inputs!$B$29+Inputs!$B$31) -> 610.22675 | G39: =G37/1000*(Inputs!$B$19+Inputs!$B$20+Inputs!$B$21+Inputs!$B$22+Inputs!$B$23+Inputs!$B$24)+G38*((((Inputs!$B$10*Inputs!$B$15+Inputs!$B$11*Inputs!$B$16)*(1-Inputs!$B$14)+(Inputs!$B$10*Inputs!$B$17+Inputs!$B$11*Inputs!$B$18)*Inputs!$B$14)/1000000*Inputs!$B$12)*$B$11+Inputs!$B$12*Inputs!$B$13)+(G35*$D$17)*Inputs!$B$25*Inputs!$B$26+((G35*$D$17)*Inputs!$B$8*$B$13)*Inputs!$B$27*Inputs!$B$28+G36*(Inputs!$B$29+Inputs!$B$31) -> 860.20132 | H39: =H37/1000*(Inputs!$B$19+Inputs!$B$20+Inputs!$B$21+Inputs!$B$22+Inputs!$B$23+Inputs!$B$24)+H38*((((Inputs!$B$10*Inputs!$B$15+Inputs!$B$11*Inputs!$B$16)*(1-Inputs!$B$14)+(Inputs!$B$10*Inputs!$B$17+Inputs!$B$11*Inputs!$B$18)*Inputs!$B$14)/1000000*Inputs!$B$12)*$B$11+Inputs!$B$12*Inputs!$B$13)+(H35*$D$17)*Inputs!$B$25*Inputs!$B$26+((H35*$D$17)*Inputs!$B$8*$B$13)*Inputs!$B$27*Inputs!$B$28+H36*(Inputs!$B$29+Inputs!$B$31) -> 1030.4184 | I39: =I37/1000*(Inputs!$B$19+Inputs!$B$20+Inputs!$B$21+Inputs!$B$22+Inputs!$B$23+Inputs!$B$24)+I38*((((Inputs!$B$10*Inputs!$B$15+Inputs!$B$11*Inputs!$B$16)*(1-Inputs!$B$14)+(Inputs!$B$10*Inputs!$B$17+Inputs!$B$11*Inputs!$B$18)*Inputs!$B$14)/1000000*Inputs!$B$12)*$B$11+Inputs!$B$12*Inputs!$B$13)+(I35*$D$17)*Inputs!$B$25*Inputs!$B$26+((I35*$D$17)*Inputs!$B$8*$B$13)*Inputs!$B$27*Inputs!$B$28+I36*(Inputs!$B$29+Inputs!$B$31) -> 1292.0609 | ... M39: =M37/1000*(Inputs!$B$19+Inputs!$B$20+Inputs!$B$21+Inputs!$B$22+Inputs!$B$23+Inputs!$B$24)+M38*((((Inputs!$B$10*Inputs!$B$15+Inputs!$B$11*Inputs!$B$16)*(1-Inputs!$B$14)+(Inputs!$B$10*Inputs!$B$17+Inputs!$B$11*Inputs!$B$18)*Inputs!$B$14)/1000000*Inputs!$B$12)*$B$11+Inputs!$B$12*Inputs!$B$13)+(M35*$D$17)*Inputs!$B$25*Inputs!$B$26+((M35*$D$17)*Inputs!$B$8*$B$13)*Inputs!$B$27*Inputs!$B$28+M36*(Inputs!$B$29+Inputs!$B$31) -> 2445.544
A41: Starter | Opening accounts | B41: =0 -> 0 | C41: =B44 -> 16.2 | D41: =C44 -> 34.425 | E41: =D44 -> 54.988875 | F41: =E44 -> 78.252328 | G41: =F44 -> 104.62992 | H41: =G44 -> 134.59816 | I41: =H44 -> 168.70479 | J41: =I44 -> 207.57949 | ... M41: =L44 -> 360.60922
A42: Starter | New accounts | B42: =B27*$C$18 -> 16.2 | C42: =C27*$C$18 -> 18.63 | D42: =D27*$C$18 -> 21.4245 | E42: =E27*$C$18 -> 24.638175 | F42: =F27*$C$18 -> 28.333901 | G42: =G27*$C$18 -> 32.583986 | H42: =H27*$C$18 -> 37.471584 | I42: =I27*$C$18 -> 43.092322 | ... M42: =M27*$C$18 -> 75.368741
A43: Starter | Churned accounts | B43: =B41*$B$7 -> 0 | C43: =C41*$B$7 -> 0.405 | D43: =D41*$B$7 -> 0.860625 | E43: =E41*$B$7 -> 1.3747219 | F43: =F41*$B$7 -> 1.9563082 | G43: =G41*$B$7 -> 2.615748 | H43: =H41*$B$7 -> 3.364954 | I43: =I41*$B$7 -> 4.2176197 | ... M43: =M41*$B$7 -> 9.0152306
A44: Starter | Ending accounts | B44: =B41+B42-B43 -> 16.2 | C44: =C41+C42-C43 -> 34.425 | D44: =D41+D42-D43 -> 54.988875 | E44: =E41+E42-E43 -> 78.252328 | F44: =F41+F42-F43 -> 104.62992 | G44: =G41+G42-G43 -> 134.59816 | H44: =H41+H42-H43 -> 168.70479 | I44: =I41+I42-I43 -> 207.57949 | ... M44: =M41+M42-M43 -> 426.96273
A45: Starter | Average accounts | B45: =(B41+B44)/2 -> 8.1 | C45: =(C41+C44)/2 -> 25.3125 | D45: =(D41+D44)/2 -> 44.706938 | E45: =(E41+E44)/2 -> 66.620602 | F45: =(F41+F44)/2 -> 91.441125 | G45: =(G41+G44)/2 -> 119.61404 | H45: =(H41+H44)/2 -> 151.65147 | I45: =(I41+I44)/2 -> 188.14214 | ... M45: =(M41+M44)/2 -> 393.78598
A46: Starter | Revenue | B46: =B45*$B$18 -> 72.9 | C46: =C45*$B$18 -> 227.8125 | D46: =D45*$B$18 -> 402.36244 | E46: =E45*$B$18 -> 599.58541 | F46: =F45*$B$18 -> 822.97012 | G46: =G45*$B$18 -> 1076.5264 | H46: =H45*$B$18 -> 1364.8633 | I46: =I45*$B$18 -> 1693.2793 | ... M46: =M45*$B$18 -> 3544.0738
A47: Starter | Monitoring checks | B47: =(B45*$D$18)*DAY(EOMONTH(B$25,0))*1440/$E$18*$B$12 -> 216950.4 | C47: =(C45*$D$18)*DAY(EOMONTH(C$25,0))*1440/$E$18*$B$12 -> 656100 | D47: =(D45*$D$18)*DAY(EOMONTH(D$25,0))*1440/$E$18*$B$12 -> 1197430.6 | E47: =(E45*$D$18)*DAY(EOMONTH(E$25,0))*1440/$E$18*$B$12 -> 1784366.2 | F47: =(F45*$D$18)*DAY(EOMONTH(F$25,0))*1440/$E$18*$B$12 -> 2212143.7 | G47: =(G45*$D$18)*DAY(EOMONTH(G$25,0))*1440/$E$18*$B$12 -> 3203742.5 | H47: =(H45*$D$18)*DAY(EOMONTH(H$25,0))*1440/$E$18*$B$12 -> 3930806.2 | I47: =(I45*$D$18)*DAY(EOMONTH(I$25,0))*1440/$E$18*$B$12 -> 5039199.1 | ... M47: =(M45*$D$18)*DAY(EOMONTH(M$25,0))*1440/$E$18*$B$12 -> 10206933
A48: Starter | AI diagnoses | B48: =(B45*$D$18)*Inputs!$B$8*$B$13*Inputs!$B$9*$F$18 -> 5.832 | C48: =(C45*$D$18)*Inputs!$B$8*$B$13*Inputs!$B$9*$F$18 -> 18.225 | D48: =(D45*$D$18)*Inputs!$B$8*$B$13*Inputs!$B$9*$F$18 -> 32.188995 | E48: =(E45*$D$18)*Inputs!$B$8*$B$13*Inputs!$B$9*$F$18 -> 47.966833 | F48: =(F45*$D$18)*Inputs!$B$8*$B$13*Inputs!$B$9*$F$18 -> 65.83761 | G48: =(G45*$D$18)*Inputs!$B$8*$B$13*Inputs!$B$9*$F$18 -> 86.122109 | H48: =(H45*$D$18)*Inputs!$B$8*$B$13*Inputs!$B$9*$F$18 -> 109.18906 | I48: =(I45*$D$18)*Inputs!$B$8*$B$13*Inputs!$B$9*$F$18 -> 135.46234 | ... M48: =(M45*$D$18)*Inputs!$B$8*$B$13*Inputs!$B$9*$F$18 -> 283.52591
A49: Starter | Variable service expense | B49: =B47/1000*(Inputs!$B$19+Inputs!$B$20+Inputs!$B$21+Inputs!$B$22+Inputs!$B$23+Inputs!$B$24)+B48*((((Inputs!$B$10*Inputs!$B$15+Inputs!$B$11*Inputs!$B$16)*(1-Inputs!$B$14)+(Inputs!$B$10*Inputs!$B$17+Inputs!$B$11*Inputs!$B$18)*Inputs!$B$14)/1000000*Inputs!$B$12)*$B$11+Inputs!$B$12*Inputs!$B$13)+(B45*$D$18)*Inputs!$B$25*Inputs!$B$26+((B45*$D$18)*Inputs!$B$8*$B$13)*Inputs!$B$27*Inputs!$B$28+B46*(Inputs!$B$29+Inputs!$B$31)+B44*Inputs!$B$30+B45*Inputs!$B$32 -> 48.588284 | C49: =C47/1000*(Inputs!$B$19+Inputs!$B$20+Inputs!$B$21+Inputs!$B$22+Inputs!$B$23+Inputs!$B$24)+C48*((((Inputs!$B$10*Inputs!$B$15+Inputs!$B$11*Inputs!$B$16)*(1-Inputs!$B$14)+(Inputs!$B$10*Inputs!$B$17+Inputs!$B$11*Inputs!$B$18)*Inputs!$B$14)/1000000*Inputs!$B$12)*$B$11+Inputs!$B$12*Inputs!$B$13)+(C45*$D$18)*Inputs!$B$25*Inputs!$B$26+((C45*$D$18)*Inputs!$B$8*$B$13)*Inputs!$B$27*Inputs!$B$28+C46*(Inputs!$B$29+Inputs!$B$31)+C44*Inputs!$B$30+C45*Inputs!$B$32 -> 143.26049 | D49: =D47/1000*(Inputs!$B$19+Inputs!$B$20+Inputs!$B$21+Inputs!$B$22+Inputs!$B$23+Inputs!$B$24)+D48*((((Inputs!$B$10*Inputs!$B$15+Inputs!$B$11*Inputs!$B$16)*(1-Inputs!$B$14)+(Inputs!$B$10*Inputs!$B$17+Inputs!$B$11*Inputs!$B$18)*Inputs!$B$14)/1000000*Inputs!$B$12)*$B$11+Inputs!$B$12*Inputs!$B$13)+(D45*$D$18)*Inputs!$B$25*Inputs!$B$26+((D45*$D$18)*Inputs!$B$8*$B$13)*Inputs!$B$27*Inputs!$B$28+D46*(Inputs!$B$29+Inputs!$B$31)+D44*Inputs!$B$30+D45*Inputs!$B$32 -> 257.84946 | E49: =E47/1000*(Inputs!$B$19+Inputs!$B$20+Inputs!$B$21+Inputs!$B$22+Inputs!$B$23+Inputs!$B$24)+E48*((((Inputs!$B$10*Inputs!$B$15+Inputs!$B$11*Inputs!$B$16)*(1-Inputs!$B$14)+(Inputs!$B$10*Inputs!$B$17+Inputs!$B$11*Inputs!$B$18)*Inputs!$B$14)/1000000*Inputs!$B$12)*$B$11+Inputs!$B$12*Inputs!$B$13)+(E45*$D$18)*Inputs!$B$25*Inputs!$B$26+((E45*$D$18)*Inputs!$B$8*$B$13)*Inputs!$B$27*Inputs!$B$28+E46*(Inputs!$B$29+Inputs!$B$31)+E44*Inputs!$B$30+E45*Inputs!$B$32 -> 383.13059 | F49: =F47/1000*(Inputs!$B$19+Inputs!$B$20+Inputs!$B$21+Inputs!$B$22+Inputs!$B$23+Inputs!$B$24)+F48*((((Inputs!$B$10*Inputs!$B$15+Inputs!$B$11*Inputs!$B$16)*(1-Inputs!$B$14)+(Inputs!$B$10*Inputs!$B$17+Inputs!$B$11*Inputs!$B$18)*Inputs!$B$14)/1000000*Inputs!$B$12)*$B$11+Inputs!$B$12*Inputs!$B$13)+(F45*$D$18)*Inputs!$B$25*Inputs!$B$26+((F45*$D$18)*Inputs!$B$8*$B$13)*Inputs!$B$27*Inputs!$B$28+F46*(Inputs!$B$29+Inputs!$B$31)+F44*Inputs!$B$30+F45*Inputs!$B$32 -> 484.74617 | G49: =G47/1000*(Inputs!$B$19+Inputs!$B$20+Inputs!$B$21+Inputs!$B$22+Inputs!$B$23+Inputs!$B$24)+G48*((((Inputs!$B$10*Inputs!$B$15+Inputs!$B$11*Inputs!$B$16)*(1-Inputs!$B$14)+(Inputs!$B$10*Inputs!$B$17+Inputs!$B$11*Inputs!$B$18)*Inputs!$B$14)/1000000*Inputs!$B$12)*$B$11+Inputs!$B$12*Inputs!$B$13)+(G45*$D$18)*Inputs!$B$25*Inputs!$B$26+((G45*$D$18)*Inputs!$B$8*$B$13)*Inputs!$B$27*Inputs!$B$28+G46*(Inputs!$B$29+Inputs!$B$31)+G44*Inputs!$B$30+G45*Inputs!$B$32 -> 686.12226 | H49: =H47/1000*(Inputs!$B$19+Inputs!$B$20+Inputs!$B$21+Inputs!$B$22+Inputs!$B$23+Inputs!$B$24)+H48*((((Inputs!$B$10*Inputs!$B$15+Inputs!$B$11*Inputs!$B$16)*(1-Inputs!$B$14)+(Inputs!$B$10*Inputs!$B$17+Inputs!$B$11*Inputs!$B$18)*Inputs!$B$14)/1000000*Inputs!$B$12)*$B$11+Inputs!$B$12*Inputs!$B$13)+(H45*$D$18)*Inputs!$B$25*Inputs!$B$26+((H45*$D$18)*Inputs!$B$8*$B$13)*Inputs!$B$27*Inputs!$B$28+H46*(Inputs!$B$29+Inputs!$B$31)+H44*Inputs!$B$30+H45*Inputs!$B$32 -> 847.03548 | I49: =I47/1000*(Inputs!$B$19+Inputs!$B$20+Inputs!$B$21+Inputs!$B$22+Inputs!$B$23+Inputs!$B$24)+I48*((((Inputs!$B$10*Inputs!$B$15+Inputs!$B$11*Inputs!$B$16)*(1-Inputs!$B$14)+(Inputs!$B$10*Inputs!$B$17+Inputs!$B$11*Inputs!$B$18)*Inputs!$B$14)/1000000*Inputs!$B$12)*$B$11+Inputs!$B$12*Inputs!$B$13)+(I45*$D$18)*Inputs!$B$25*Inputs!$B$26+((I45*$D$18)*Inputs!$B$8*$B$13)*Inputs!$B$27*Inputs!$B$28+I46*(Inputs!$B$29+Inputs!$B$31)+I44*Inputs!$B$30+I45*Inputs!$B$32 -> 1077.9693 | ... M49: =M47/1000*(Inputs!$B$19+Inputs!$B$20+Inputs!$B$21+Inputs!$B$22+Inputs!$B$23+Inputs!$B$24)+M48*((((Inputs!$B$10*Inputs!$B$15+Inputs!$B$11*Inputs!$B$16)*(1-Inputs!$B$14)+(Inputs!$B$10*Inputs!$B$17+Inputs!$B$11*Inputs!$B$18)*Inputs!$B$14)/1000000*Inputs!$B$12)*$B$11+Inputs!$B$12*Inputs!$B$13)+(M45*$D$18)*Inputs!$B$25*Inputs!$B$26+((M45*$D$18)*Inputs!$B$8*$B$13)*Inputs!$B$27*Inputs!$B$28+M46*(Inputs!$B$29+Inputs!$B$31)+M44*Inputs!$B$30+M45*Inputs!$B$32 -> 2196.1243
A51: Pro | Opening accounts | B51: =0 -> 0 | C51: =B54 -> 14.4 | D51: =C54 -> 30.6 | E51: =D54 -> 48.879 | F51: =E54 -> 69.557625 | G51: =F54 -> 93.004374 | H51: =G54 -> 119.64281 | I51: =H54 -> 149.95981 | J51: =I54 -> 184.5151 | ... M51: =L54 -> 320.54153
A52: Pro | New accounts | B52: =B27*$C$19 -> 14.4 | C52: =C27*$C$19 -> 16.56 | D52: =D27*$C$19 -> 19.044 | E52: =E27*$C$19 -> 21.9006 | F52: =F27*$C$19 -> 25.18569 | G52: =G27*$C$19 -> 28.963544 | H52: =H27*$C$19 -> 33.308075 | I52: =I27*$C$19 -> 38.304286 | ... M52: =M27*$C$19 -> 66.994436
A53: Pro | Churned accounts | B53: =B51*$B$7 -> 0 | C53: =C51*$B$7 -> 0.36 | D53: =D51*$B$7 -> 0.765 | E53: =E51*$B$7 -> 1.221975 | F53: =F51*$B$7 -> 1.7389406 | G53: =G51*$B$7 -> 2.3251094 | H53: =H51*$B$7 -> 2.9910702 | I53: =I51*$B$7 -> 3.7489953 | ... M53: =M51*$B$7 -> 8.0135383
...

Sheet Guardrailed
A1: Guardrailed — hypothetical 12-month forecast
A4: Initial monthly signups | B4: =Inputs!$B$2 -> 150
A5: Monthly signup growth | B5: =Inputs!$B$3 -> 0.1
A6: Paid conversion rate | B6: =Inputs!$B$4 -> 0.08
A7: Monthly paid churn | B7: =Inputs!$B$5 -> 0.04
A8: Monthly free churn | B8: =Inputs!$B$6 -> 0.15
A9: Blended acquisition CAC | B9: =Inputs!$B$7 -> 40
A10: Staff monthly budget | B10: 0
A11: AI cost stress multiplier | B11: =Inputs!$B$50 -> 1
A12: Monitoring frequency multiplier | B12: =Inputs!$B$51 -> 1
A13: Incident volume multiplier | B13: =Inputs!$B$52 -> 1
